Workbook

Sheet UBER 2025
M1: -10
A2: SEM | B2: CONDUCTOR | C2: AUTO | D2: TAG | E2: SOCIO | F2: PLATAFORMA | G2: APP | H2: GANANCIA | I2: IMPUESTOS | J2: P. AJUSANT | K2: SEGURO | L2: EFECTIVO | M2: PAGO A TERCEROS | N2: TAG | O2: UBER tot | P2: RENTA | Q2: SEM PASADA | R2: FIANZA | S2: MULTA | T2: HOJALATERO | U2: DESCUENTOS | V2: FA | W2: TOTAL | X2: PAGOS | Y2: DEVOLUCIONES | Z2: PAGADO | AA2: ADEUDO | AB2: GANANCIAS TOTALES | AC2: COMENTARIOS
A3: 1 | B3: ADOLFO LOPEZ MARTINEZ | C3: AVEO|2021|OCRE|NEB156A | D3: OHLM023012552 | E3: ASHC | F3: IVETH | G3: UBER | H3: 1943.26 | I3: -16 | J3: 0 | K3: 0 | L3: -758.4 | M3: =-38.8652+32 -> -6.8652 | N3: 0 | O3: =SUM(H3:N3) -> 1161.9948 | P3: -2142.85 | Q3: 0 | R3: 0 | S3: 0 | T3: 0 | U3: 0 | V3: 0 | W3: =+O3+SUM(P3:V3) -> -980.8552 | X3: =IF(W3>=0,W3,0) -> 0 | Y3: =IF(W3<=0,W3,0) -> -980.8552 | Z3: 981 | AA3: =+Y3+Z3 -> 0.1448 | AB3: =+O3-X3+Z3+AA3 -> 2143.1396 | AD3: NEB156A | AE3: =AD3&A3 -> NEB156A1
A4: 1 | B4: ARACELI CASTILLO GUERRERO | C4: AVEO|2018|GRIS|X59AWG | D4: - | E4: ASHC | F4: ASHC | G4: UBER | H4: 6825.48 | I4: -448 | J4: 0 | K4: 0 | L4: -1537.44 | M4: -136.5096 | N4: 0 | O4: =SUM(H4:N4) -> 4703.5304 | P4: -2142.85 | Q4: 0 | R4: 0 | S4: 0 | T4: 0 | U4: 0 | V4: 0 | W4: =+O4+SUM(P4:V4) -> 2560.6804 | X4: =IF(W4>=0,W4,0) -> 2560.6804 | Y4: =IF(W4<=0,W4,0) -> 0 | Z4: 0 | AA4: =+Y4+Z4 -> 0 | AB4: =+O4-X4+Z4+AA4 -> 2142.85 | AD4: =VLOOKUP($C4,'[1]CTRL AUTOS'!$E:$AH,2,0) -> X59AWG | AE4: =AD4&A4 -> X59AWG1
A5: 1 | B5: CESAR PIÑA BARONA | C5: HYUNDAI|2022|PLATA|D40BKD | D5: OHLM023658024 | E5: ASHC | F5: IVETH | G5: UBER | H5: 0 | I5: 0 | J5: 0 | K5: 0 | L5: 0 | M5: 0 | N5: 0 | O5: =SUM(H5:N5) -> 0 | P5: -2142.85 | Q5: -67 | R5: 0 | S5: 0 | T5: 0 | U5: 0 | V5: 0 | W5: =+O5+SUM(P5:V5) -> -2209.85 | X5: =IF(W5>=0,W5,0) -> 0 | Y5: =IF(W5<=0,W5,0) -> -2209.85 | Z5: 2210 | AA5: =+Y5+Z5 -> 0.15 | AB5: =+O5-X5+Z5+AA5 -> 2210.15 | AD5: =VLOOKUP($C5,'[1]CTRL AUTOS'!$E:$AH,2,0) -> D40BKD | AE5: =AD5&A5 -> D40BKD1
A6: 1 | B6: CLAUDIA LEAÑOS | C6: KIA RIO|2017|ROJO|MYE912A | D6: - | E6: U64 | F6: ASHC | G6: UBER | H6: 3855.54 | I6: -30.4 | J6: 0 | K6: 0 | L6: -2145.89 | M6: -77.1108 | N6: 0 | O6: =SUM(H6:N6) -> 1602.1392 | P6: -2142.85 | Q6: -510.28 | R6: 0 | S6: 0 | T6: 0 | U6: 0 | V6: 0 | W6: =+O6+SUM(P6:V6) -> -1050.9908 | X6: =IF(W6>=0,W6,0) -> 0 | Y6: =IF(W6<=0,W6,0) -> -1050.9908 | Z6: 1051 | AA6: =+Y6+Z6 -> 0.0092 | AB6: =+O6-X6+Z6+AA6 -> 2653.1484 | AD6: =VLOOKUP($C6,'[1]CTRL AUTOS'!$E:$AH,2,0) -> MYE912A | AE6: =AD6&A6 -> MYE912A1
A7: 1 | B7: IVAN MOGUEL PULIDO | C7: VERSA|2023|PLATA|NCT814A | D7: OHLM023012487 | E7: ASHC | F7: ASHC | G7: UBER | H7: 3884.89 | I7: 0 | J7: 0 | K7: 0 | L7: -2355.1 | M7: -90.2478 | N7: -70.97 | O7: =SUM(H7:N7) -> 1368.5722 | P7: -714.28 | Q7: 0 | R7: 0 | S7: 0 | T7: -500 | U7: 0 | V7: 0 | W7: =+O7+SUM(P7:V7) -> 154.2922 | X7: =IF(W7>=0,W7,0) -> 154.2922 | Y7: =IF(W7<=0,W7,0) -> 0 | Z7: 0 | AA7: =+Y7+Z7 -> 0 | AB7: =+O7-X7+Z7+AA7 -> 1214.28 | AD7: =VLOOKUP($C7,'[1]CTRL AUTOS'!$E:$AH,2,0) -> NCT814A | AE7: =AD7&A7 -> NCT814A1
A8: 1 | B8: JESUS AURELIO NUNGARAY CASTILLO | C8: VENTO|2020|GRIS|R66BER | D8: - | E8: ASHC | F8: ASHC | G8: UBER | H8: 4885.68 | I8: 0 | J8: 0 | K8: 0 | L8: -2620.14 | M8: -97.7136 | N8: 0 | O8: =SUM(H8:N8) -> 2167.8264 | P8: -2142.85 | Q8: -683.71 | R8: 0 | S8: 0 | T8: 0 | U8: 0 | V8: 0 | W8: =+O8+SUM(P8:V8) -> -658.7336 | X8: =IF(W8>=0,W8,0) -> 0 | Y8: =IF(W8<=0,W8,0) -> -658.7336 | Z8: 659 | AA8: =+Y8+Z8 -> 0.2664 | AB8: =+O8-X8+Z8+AA8 -> 2827.0928 | AD8: =VLOOKUP($C8,'[1]CTRL AUTOS'!$E:$AH,2,0) -> R66BER | AE8: =AD8&A8 -> R66BER1
A9: 1 | B9: JORGE VAZQUEZ HERNANDEZ | C9: AVEO|2018|GRIS|X59AWG | D9: - | E9: ASHC | F9: ASHC | G9: UBER | H9: 9781.33 | I9: 0 | J9: 0 | K9: 0 | L9: -4655.05 | M9: -195.6266 | N9: 0 | O9: =SUM(H9:N9) -> 4930.6534 | P9: -2142.85 | Q9: 0 | R9: 0 | S9: 0 | T9: 0 | U9: 0 | V9: 0 | W9: =+O9+SUM(P9:V9) -> 2787.8034 | X9: =IF(W9>=0,W9,0) -> 2787.8034 | Y9: =IF(W9<=0,W9,0) -> 0 | Z9: 0 | AA9: =+Y9+Z9 -> 0 | AB9: =+O9-X9+Z9+AA9 -> 2142.85 | AD9: =VLOOKUP($C9,'[1]CTRL AUTOS'!$E:$AH,2,0) -> X59AWG | AE9: =AD9&A9 -> X59AWG1
A10: 1 | B10: JOSE GUADALUPE GARCIA MORALES | C10: MARCH|2020|TURQ|N15BKD | D10: OHLM031409071 | E10: ASHC | F10: ASHC | G10: UBER | H10: 5089.85 | I10: -24 | J10: 0 | K10: 0 | L10: -3520.73 | M10: =-101.797+48 -> -53.797 | N10: 0 | O10: =SUM(H10:N10) -> 1491.323 | P10: -2142.85 | Q10: 0 | R10: -500 | S10: 0 | T10: 0 | U10: 0 | V10: 0 | W10: =+O10+SUM(P10:V10) -> -1151.527 | X10: =IF(W10>=0,W10,0) -> 0 | Y10: =IF(W10<=0,W10,0) -> -1151.527 | Z10: 1152 | AA10: =+Y10+Z10 -> 0.473 | AB10: =+O10-X10+Z10+AA10 -> 2643.796 | AD10: =VLOOKUP($C10,'[1]CTRL AUTOS'!$E:$AH,2,0) -> N15BKD | AE10: =AD10&A10 -> N15BKD1
A11: 1 | B11: JOSE JUAN HERNANDEZ MEJIA | C11: VERSA|2017|ACERO|X24APU | D11: OHLM023720345 | E11: ASHC | F11: ASHC | G11: UBER | H11: 4940.33 | I11: -38.4 | J11: 0 | K11: 0 | L11: -2048.73 | M11: =-98.8066+77 -> -21.8066 | N11: 0 | O11: =SUM(H11:N11) -> 2831.3934 | P11: -2142.85 | Q11: -375.31 | R11: -500 | S11: 0 | T11: 0 | U11: 0 | V11: 0 | W11: =+O11+SUM(P11:V11) -> -186.7666 | X11: =IF(W11>=0,W11,0) -> 0 | Y11: =IF(W11<=0,W11,0) -> -186.7666 | Z11: 187 | AA11: =+Y11+Z11 -> 0.2334 | AB11: =+O11-X11+Z11+AA11 -> 3018.6268 | AD11: X24APU | AE11: =AD11&A11 -> X24APU1
A12: 1 | B12: OSCAR BLANCAS NORIEGA | C12: VENTO|2017|GRIS|NZV7888 | D12: OHLM023720279 | E12: ASHC | F12: ASHC | G12: UBER | H12: 4068.3 | I12: -38.4 | J12: 0 | K12: 0 | L12: -935.09 | M12: =-81.366+77 -> -4.366 | N12: 0 | O12: =SUM(H12:N12) -> 3090.444 | P12: -1971.42 | Q12: -1063 | R12: -500 | S12: 0 | T12: 0 | U12: 0 | V12: 0 | W12: =+O12+SUM(P12:V12) -> -443.976 | X12: =IF(W12>=0,W12,0) -> 0 | Y12: =IF(W12<=0,W12,0) -> -443.976 | Z12: 444 | AA12: =+Y12+Z12 -> 0.024 | AB12: =+O12-X12+Z12+AA12 -> 3534.468 | AD12: BAJA DE PLACAS | AE12: =AD12&A12 -> BAJA DE PLACAS1
A13: 1 | B13: ULISES ITIEL CASTILLO AVILA | C13: KIA RIO|2020|GRIS|NCK475B | D13: OHLM031397326 | E13: ASHC | F13: IVETH | G13: UBER | H13: 5393.23 | I13: -68.8 | J13: 0 | K13: 0 | L13: -2447.29 | M13: -107.8646 | N13: 0 | O13: =SUM(H13:N13) -> 2769.2754 | P13: -2142.85 | Q13: 0 | R13: 0 | S13: 0 | T13: 0 | U13: 0 | V13: 0 | W13: =+O13+SUM(P13:V13) -> 626.4254 | X13: =IF(W13>=0,W13,0) -> 626.4254 | Y13: =IF(W13<=0,W13,0) -> 0 | Z13: 0 | AA13: =+Y13+Z13 -> 0 | AB13: =+O13-X13+Z13+AA13 -> 2142.85 | AD13: =VLOOKUP($C13,'[1]CTRL AUTOS'!$E:$AH,2,0) -> NCK475B | AE13: =AD13&A13 -> NCK475B1
A14: 2 | B14: ABRAHAM ESCOBEDO ESCALANTE | C14: BEAT|2020|GRIS|NFN014B | D14: - | E14: U64 | F14: ASHC | G14: UBER | H14: 1382.8 | I14: -22.4 | J14: 0 | K14: 0 | L14: -723.89 | M14: -27.656 | N14: 0 | O14: =SUM(H14:N14) -> 608.854 | P14: -1428.56 | Q14: 0 | R14: 0 | S14: 0 | T14: 0 | U14: 0 | V14: 0 | W14: =+O14+SUM(P14:V14) -> -819.706 | X14: =IF(W14>=0,W14,0) -> 0 | Y14: =IF(W14<=0,W14,0) -> -819.706 | Z14: 0 | AA14: =+Y14+Z14 -> -819.706 | AB14: =+O14-X14+Z14+AA14 -> -210.852 | AC14: PÉRDIDA | AD14: =VLOOKUP($C14,'[1]CTRL AUTOS'!$E:$AH,2,0) -> NFN014B | AE14: =AD14&A14 -> NFN014B2
A15: 2 | B15: ADOLFO LOPEZ MARTINEZ | C15: AVEO|2021|OCRE|NEB156A | D15: OHLM023012552 | E15: ASHC | F15: IVETH | G15: UBER | H15: 0 | I15: 0 | J15: 0 | K15: 0 | L15: 0 | M15: 0 | N15: 0 | O15: =SUM(H15:N15) -> 0 | P15: -2500 | Q15: 0 | R15: 0 | S15: 0 | T15: 0 | U15: 0 | V15: 0 | W15: =+O15+SUM(P15:V15) -> -2500 | X15: =IF(W15>=0,W15,0) -> 0 | Y15: =IF(W15<=0,W15,0) -> -2500 | Z15: 2500 | AA15: =+Y15+Z15 -> 0 | AB15: =+O15-X15+Z15+AA15 -> 2500 | AD15: NEB156A | AE15: =AD15&A15 -> NEB156A2
A16: 2 | B16: ARACELI CASTILLO GUERRERO | C16: AVEO|2018|GRIS|X59AWG | D16: - | E16: ASHC | F16: ASHC | G16: UBER | H16: 3130.3 | I16: 0 | J16: 0 | K16: 0 | L16: -1220.45 | M16: -62.606 | N16: 0 | O16: =SUM(H16:N16) -> 1847.244 | P16: -2500 | Q16: 0 | R16: 0 | S16: 0 | T16: 0 | U16: 0 | V16: 0 | W16: =+O16+SUM(P16:V16) -> -652.756 | X16: =IF(W16>=0,W16,0) -> 0 | Y16: =IF(W16<=0,W16,0) -> -652.756 | Z16: 653 | AA16: =+Y16+Z16 -> 0.244 | AB16: =+O16-X16+Z16+AA16 -> 2500.488 | AD16: =VLOOKUP($C16,'[1]CTRL AUTOS'!$E:$AH,2,0) -> X59AWG | AE16: =AD16&A16 -> X59AWG2
A17: 2 | B17: CESAR PIÑA BARONA | C17: HYUNDAI|2022|PLATA|D40BKD | D17: OHLM023658024 | E17: ASHC | F17: IVETH | G17: UBER | H17: 0 | I17: 0 | J17: 0 | K17: 0 | L17: 0 | M17: 0 | N17: 0 | O17: =SUM(H17:N17) -> 0 | P17: -2500 | Q17: 0 | R17: 0 | S17: 0 | T17: 0 | U17: 0 | V17: 0 | W17: =+O17+SUM(P17:V17) -> -2500 | X17: =IF(W17>=0,W17,0) -> 0 | Y17: =IF(W17<=0,W17,0) -> -2500 | Z17: 2500 | AA17: =+Y17+Z17 -> 0 | AB17: =+O17-X17+Z17+AA17 -> 2500 | AD17: =VLOOKUP($C17,'[1]CTRL AUTOS'!$E:$AH,2,0) -> D40BKD | AE17: =AD17&A17 -> D40BKD2
A18: 2 | B18: CLAUDIA LEAÑOS | C18: KIA RIO|2017|ROJO|MYE912A | D18: - | E18: U64 | F18: ASHC | G18: UBER | H18: 3759.89 | I18: -60.8 | J18: 0 | K18: 0 | L18: -1578.07 | M18: -75.1978 | N18: 0 | O18: =SUM(H18:N18) -> 2045.8222 | P18: -2500 | Q18: 0 | R18: 0 | S18: 0 | T18: 0 | U18: 0 | V18: 0 | W18: =+O18+SUM(P18:V18) -> -454.1778 | X18: =IF(W18>=0,W18,0) -> 0 | Y18: =IF(W18<=0,W18,0) -> -454.1778 | Z18: 0 | AA18: =+Y18+Z18 -> -454.1778 | AB18: =+O18-X18+Z18+AA18 -> 1591.6444 | AC18: PÉRDIDA | AD18: =VLOOKUP($C18,'[1]CTRL AUTOS'!$E:$AH,2,0) -> MYE912A | AE18: =AD18&A18 -> MYE912A2
A19: 2 | B19: DIEGO SANCHEZ | C19: VENTO|2020|GRIS|R66BER | D19: OHLM023720329 | E19: ASHC | F19: ASHC | G19: UBER | H19: 2574.35 | I19: 0 | J19: 0 | K19: 0 | L19: -1659.48 | M19: -51.487 | N19: 0 | O19: =SUM(H19:N19) -> 863.383 | P19: -1428.56 | Q19: 0 | R19: -500 | S19: 0 | T19: 0 | U19: 0 | V19: 0 | W19: =+O19+SUM(P19:V19) -> -1065.177 | X19: =IF(W19>=0,W19,0) -> 0 | Y19: =IF(W19<=0,W19,0) -> -1065.177 | Z19: 1065 | AA19: =+Y19+Z19 -> -0.177 | AB19: =+O19-X19+Z19+AA19 -> 1928.206 | AD19: =VLOOKUP($C19,'[1]CTRL AUTOS'!$E:$AH,2,0) -> R66BER | AE19: =AD19&A19 -> R66BER2
A20: 2 | B20: EDGAR GEOVANY URIBE | C20: AVEO|2019|PLATA|NEL860A | D20: OHLM023720337 | E20: ASHC | F20: ASHC | G20: UBER | H20: 4536.98 | I20: -119.2 | J20: 0 | K20: 0 | L20: -898.58 | M20: -113.3596 | N20: 0 | O20: =SUM(H20:N20) -> 3405.8404 | P20: -2500 | Q20: 0 | R20: 0 | S20: -500 | T20: 0 | U20: 0 | V20: 0 | W20: =+O20+SUM(P20:V20) -> 405.8404 | X20: =IF(W20>=0,W20,0) -> 405.8404 | Y20: =IF(W20<=0,W20,0) -> 0 | Z20: 0 | AA20: =+Y20+Z20 -> 0 | AB20: =+O20-X20+Z20+AA20 -> 3000 | AD20: =VLOOKUP($C20,'[1]CTRL AUTOS'!$E:$AH,2,0) -> NEL860A | AE20: =AD20&A20 -> NEL860A2
A21: 2 | B21: IRAM HERNANDEZ | C21: AVEO|2022|AZUL|MUF515A | D21: OHLM023720311 | E21: ASHC | F21: ASHC | G21: UBER | H21: 6165.24 | I21: 0 | J21: 0 | K21: 0 | L21: -2465.51 | M21: -123.3048 | N21: 0 | O21: =SUM(H21:N21) -> 3576.4252 | P21: -2500 | Q21: 0 | R21: 0 | S21: -500 | T21: 0 | U21: 0 | V21: 0 | W21: =+O21+SUM(P21:V21) -> 576.4252 | X21: =IF(W21>=0,W21,0) -> 576.4252 | Y21: =IF(W21<=0,W21,0) -> 0 | Z21: 0 | AA21: =+Y21+Z21 -> 0 | AB21: =+O21-X21+Z21+AA21 -> 3000 | AD21: =VLOOKUP($C21,'[1]CTRL AUTOS'!$E:$AH,2,0) -> MUF515A | AE21: =AD21&A21 -> MUF515A2
A22: 2 | B22: IVAN MOGUEL PULIDO | C22: VERSA|2023|PLATA|NCT814A | D22: OHLM023012487 | E22: ASHC | F22: ASHC | G22: UBER | H22: 11072.8 | I22: -262.4 | J22: 0 | K22: 0 | L22: -4296.05 | M22: -221.456 | N22: -46 | O22: =SUM(H22:N22) -> 6246.894 | P22: -2500 | Q22: 0 | R22: 0 | S22: 0 | T22: -500 | U22: 0 | V22: 0 | W22: =+O22+SUM(P22:V22) -> 3246.894 | X22: =IF(W22>=0,W22,0) -> 3246.894 | Y22: =IF(W22<=0,W22,0) -> 0 | Z22: 0 | AA22: =+Y22+Z22 -> 0 | AB22: =+O22-X22+Z22+AA22 -> 3000 | AD22: =VLOOKUP($C22,'[1]CTRL AUTOS'!$E:$AH,2,0) -> NCT814A | AE22: =AD22&A22 -> NCT814A2
A23: 2 | B23: JESUS AURELIO NUNGARAY CASTILLO | C23: VENTO|2020|GRIS|R66BER | D23: - | E23: ASHC | F23: ASHC | G23: UBER | H23: 2251.02 | I23: 0 | J23: 0 | K23: 0 | L23: -1814.27 | M23: -45.0204 | N23: -127.82 | O23: =SUM(H23:N23) -> 263.9096 | P23: -714.28 | Q23: 0 | R23: 0 | S23: 0 | T23: 0 | U23: 0 | V23: 0 | W23: =+O23+SUM(P23:V23) -> -450.3704 | X23: =IF(W23>=0,W23,0) -> 0 | Y23: =IF(W23<=0,W23,0) -> -450.3704 | Z23: 450 | AA23: =+Y23+Z23 -> -0.3704 | AB23: =+O23-X23+Z23+AA23 -> 713.5392 | AD23: =VLOOKUP($C23,'[1]CTRL AUTOS'!$E:$AH,2,0) -> R66BER | AE23: =AD23&A23 -> R66BER2
A24: 2 | B24: JORGE VAZQUEZ HERNANDEZ | C24: AVEO|2018|GRIS|X59AWG | D24: - | E24: ASHC | F24: ASHC | G24: UBER | H24: 3233.43 | I24: 0 | J24: 0 | K24: 0 | L24: -628.14 | M24: -64.6686 | N24: 0 | O24: =SUM(H24:N24) -> 2540.6214 | P24: -2500 | Q24: 0 | R24: 0 | S24: 0 | T24: 0 | U24: 0 | V24: 0 | W24: =+O24+SUM(P24:V24) -> 40.6214 | X24: =IF(W24>=0,W24,0) -> 40.6214 | Y24: =IF(W24<=0,W24,0) -> 0 | Z24: 0 | AA24: =+Y24+Z24 -> 0 | AB24: =+O24-X24+Z24+AA24 -> 2500 | AD24: =VLOOKUP($C24,'[1]CTRL AUTOS'!$E:$AH,2,0) -> X59AWG | AE24: =AD24&A24 -> X59AWG2
A25: 2 | B25: JOSE GUADALUPE GARCIA MORALES | C25: MARCH|2020|TURQ|N15BKD | D25: OHLM031409071 | E25: ASHC | F25: ASHC | G25: UBER | H25: 5208.21 | I25: 0 | J25: 0 | K25: 0 | L25: -3087.32 | M25: -104.1642 | N25: 0 | O25: =SUM(H25:N25) -> 2016.7258 | P25: -2500 | Q25: -1151.53 | R25: -500 | S25: 0 | T25: 0 | U25: 0 | V25: 0 | W25: =+O25+SUM(P25:V25) -> -2134.8042 | X25: =IF(W25>=0,W25,0) -> 0 | Y25: =IF(W25<=0,W25,0) -> -2134.8042 | Z25: 2135 | AA25: =+Y25+Z25 -> 0.1958 | AB25: =+O25-X25+Z25+AA25 -> 4151.9216 | AD25: =VLOOKUP($C25,'[1]CTRL AUTOS'!$E:$AH,2,0) -> N15BKD | AE25: =AD25&A25 -> N15BKD2
A26: 2 | B26: JOSE GUILLERMO HERNANDEZ RAMIREZ | C26: AVEO|2018|ROJO|R51BKD | D26: OHLM017365206 | E26: U64 | F26: ASHC | G26: UBER | H26: 6685.99 | I26: -164.8 | J26: 0 | K26: 0 | L26: -3647.5 | M26: -133.7198 | N26: 0 | O26: =SUM(H26:N26) -> 2739.9702 | P26: -2500 | Q26: 0 | R26: 0 | S26: 0 | T26: 0 | U26: 0 | V26: 0 | W26: =+O26+SUM(P26:V26) -> 239.9702 | X26: =IF(W26>=0,W26,0) -> 239.9702 | Y26: =IF(W26<=0,W26,0) -> 0 | Z26: 0 | AA26: =+Y26+Z26 -> 0 | AB26: =+O26-X26+Z26+AA26 -> 2500 | AD26: =VLOOKUP($C26,'[1]CTRL AUTOS'!$E:$AH,2,0) -> R51BKD | AE26: =AD26&A26 -> R51BKD2
A27: 2 | B27: JOSE JUAN HERNANDEZ MEJIA | C27: VERSA|2017|ACERO|X24APU | D27: OHLM023720345 | E27: ASHC | F27: ASHC | G27: UBER | H27: 3188.12 | I27: -48 | J27: 0 | K27: 0 | L27: -1867.2 | M27: -63.7624 | N27: 0 | O27: =SUM(H27:N27) -> 1209.1576 | P27: -2500 | Q27: -186.97 | R27: -500 | S27: 0 | T27: 0 | U27: 0 | V27: 0 | W27: =+O27+SUM(P27:V27) -> -1977.8124 | X27: =IF(W27>=0,W27,0) -> 0 | Y27: =IF(W27<=0,W27,0) -> -1977.8124 | Z27: 1882 | AA27: =+Y27+Z27 -> -95.8124 | AB27: =+O27-X27+Z27+AA27 -> 2995.3452 | AD27: X24APU | AE27: =AD27&A27 -> X24APU2
A28: 2 | B28: OSCAR BLANCAS NORIEGA | C28: VENTO|2017|GRIS|NZV7888 | D28: OHLM023720279 | E28: ASHC | F28: ASHC | G28: UBER | H28: 4151.87 | I28: -81.6 | J28: 0 | K28: 0 | L28: -1247.87 | M28: -83.0374 | N28: 0 | O28: =SUM(H28:N28) -> 2739.3626 | P28: -2300 | Q28: 0 | R28: -339 | S28: -257 | T28: 0 | U28: 0 | V28: 0 | W28: =+O28+SUM(P28:V28) -> -156.6374 | X28: =IF(W28>=0,W28,0) -> 0 | Y28: =IF(W28<=0,W28,0) -> -156.6374 | Z28: 157 | AA28: =+Y28+Z28 -> 0.3626 | AB28: =+O28-X28+Z28+AA28 -> 2896.7252 | AD28: BAJA DE PLACAS | AE28: =AD28&A28 -> BAJA DE PLACAS2
A29: 2 | B29: ULISES ITIEL CASTILLO AVILA | C29: KIA RIO|2020|GRIS|NCK475B | D29: OHLM031397326 | E29: ASHC | F29: IVETH | G29: UBER | H29: 7618.92 | I29: -139.2 | J29: 0 | K29: 0 | L29: -4430.72 | M29: -152.3784 | N29: 0 | O29: =SUM(H29:N29) -> 2896.6216 | P29: -2500 | Q29: 0 | R29: 0 | S29: 0 | T29: 0 | U29: 0 | V29: 0 | W29: =+O29+SUM(P29:V29) -> 396.6216 | X29: =IF(W29>=0,W29,0) -> 396.6216 | Y29: =IF(W29<=0,W29,0) -> 0 | Z29: 0 | AA29: =+Y29+Z29 -> 0 | AB29: =+O29-X29+Z29+AA29 -> 2500 | AD29: =VLOOKUP($C29,'[1]CTRL AUTOS'!$E:$AH,2,0) -> NCK475B | AE29: =AD29&A29 -> NCK475B2
A30: 3 | B30: ABRAHAM ESCOBEDO ESCALANTE | C30: BEAT|2020|GRIS|NFN014B | D30: - | E30: U64 | F30: ASHC | G30: UBER | H30: 2639.76 | I30: 0 | J30: 0 | K30: 0 | L30: -2186.24 | M30: -52.7952 | N30: 0 | O30: =SUM(H30:N30) -> 400.7248 | P30: -2500 | Q30: -35 | R30: 0 | S30: 0 | T30: 0 | U30: 0 | V30: 0 | W30: =+O30+SUM(P30:V30) -> -2134.2752 | X30: =IF(W30>=0,W30,0) -> 0 | Y30: =IF(W30<=0,W30,0) -> -2134.2752 | Z30: 0 | AA30: =+Y30+Z30 -> -2134.2752 | AB30: =+O30-X30+Z30+AA30 -> -1733.5504 | AC30: PÉRDIDA | AD30: =VLOOKUP($C30,'[1]CTRL AUTOS'!$E:$AH,2,0) -> NFN014B | AE30: =AD30&A30 -> NFN014B3
A31: 3 | B31: ADOLFO LOPEZ MARTINEZ | C31: AVEO|2021|OCRE|NEB156A | D31: OHLM023012552 | E31: ASHC | F31: ASHC | G31: UBER | H31: 50.31 | I31: 0 | J31: 0 | K31: 0 | L31: 0 | M31: 0 | N31: 0 | O31: =SUM(H31:N31) -> 50.31 | P31: -1071 | Q31: 0 | R31: 0 | S31: 0 | T31: 0 | U31: 0 | V31: 0 | W31: =+O31+SUM(P31:V31) -> -1020.69 | X31: =IF(W31>=0,W31,0) -> 0 | Y31: =IF(W31<=0,W31,0) -> -1020.69 | Z31: 1021 | AA31: =+Y31+Z31 -> 0.31 | AB31: =+O31-X31+Z31+AA31 -> 1071.62 | AD31: NEB156A | AE31: =AD31&A31 -> NEB156A3
A32: 3 | B32: ADOLFO LOPEZ MARTINEZ | C32: AVEO|2021|OCRE|NEB156A | D32: OHLM023012552 | E32: ASHC | F32: IVETH | G32: UBER | H32: 1787.03 | I32: 0 | J32: 0 | K32: 0 | L32: -586.14 | M32: -35.7406 | N32: 0 | O32: =SUM(H32:N32) -> 1165.1494 | P32: -1429 | Q32: 0 | R32: 0 | S32: 0 | T32: 0 | U32: 0 | V32: 0 | W32: =+O32+SUM(P32:V32) -> -263.8506 | X32: =IF(W32>=0,W32,0) -> 0 | Y32: =IF(W32<=0,W32,0) -> -263.8506 | Z32: 264 | AA32: =+Y32+Z32 -> 0.1494 | AB32: =+O32-X32+Z32+AA32 -> 1429.2988 | AD32: NEB156A | AE32: =AD32&A32 -> NEB156A3
A33: 3 | B33: ARACELI CASTILLO GUERRERO | C33: AVEO|2018|GRIS|X59AWG | D33: - | E33: ASHC | F33: ASHC | G33: UBER | H33: 3737.75 | I33: 0 | J33: 0 | K33: 0 | L33: -1707.4 | M33: -74.755 | N33: 0 | O33: =SUM(H33:N33) -> 1955.595 | P33: -2500 | Q33: 0 | R33: 0 | S33: 0 | T33: 0 | U33: 0 | V33: 0 | W33: =+O33+SUM(P33:V33) -> -544.405 | X33: =IF(W33>=0,W33,0) -> 0 | Y33: =IF(W33<=0,W33,0) -> -544.405 | Z33: 544 | AA33: =+Y33+Z33 -> -0.405 | AB33: =+O33-X33+Z33+AA33 -> 2499.19 | AD33: =VLOOKUP($C33,'[1]CTRL AUTOS'!$E:$AH,2,0) -> X59AWG | AE33: =AD33&A33 -> X59AWG3
A34: 3 | B34: CESAR PIÑA BARONA | C34: HYUNDAI|2022|PLATA|D40BKD | D34: OHLM023658024 | E34: ASHC | F34: ASHC | G34: UBER | H34: 0 | I34: 0 | J34: 0 | K34: 0 | L34: 0 | M34: 0 | N34: 0 | O34: =SUM(H34:N34) -> 0 | P34: -1071 | Q34: -1300 | R34: 0 | S34: 0 | T34: 0 | U34: 0 | V34: 0 | W34: =+O34+SUM(P34:V34) -> -2371 | X34: =IF(W34>=0,W34,0) -> 0 | Y34: =IF(W34<=0,W34,0) -> -2371 | Z34: 2371 | AA34: =+Y34+Z34 -> 0 | AB34: =+O34-X34+Z34+AA34 -> 2371 | AC34: PAGADO | AD34: =VLOOKUP($C34,'[1]CTRL AUTOS'!$E:$AH,2,0) -> D40BKD | AE34: =AD34&A34 -> D40BKD3
A35: 3 | B35: CESAR PIÑA BARONA | C35: HYUNDAI|2022|PLATA|D40BKD | D35: OHLM023658024 | E35: ASHC | F35: IVETH | G35: UBER | H35: 0 | I35: 0 | J35: 0 | K35: 0 | L35: 0 | M35: 0 | N35: 0 | O35: =SUM(H35:N35) -> 0 | P35: -1429 | Q35: 0 | R35: 0 | S35: 0 | T35: 0 | U35: 0 | V35: 0 | W35: =+O35+SUM(P35:V35) -> -1429 | X35: =IF(W35>=0,W35,0) -> 0 | Y35: =IF(W35<=0,W35,0) -> -1429 | Z35: 1429 | AA35: =+Y35+Z35 -> 0 | AB35: =+O35-X35+Z35+AA35 -> 1429 | AC35: PAGADO | AD35: =VLOOKUP($C35,'[1]CTRL AUTOS'!$E:$AH,2,0) -> D40BKD | AE35: =AD35&A35 -> D40BKD3
A36: 3 | B36: CLAUDIA LEAÑOS | C36: KIA RIO|2017|ROJO|MYE912A | D36: - | E36: U64 | F36: ASHC | G36: UBER | H36: 449.82 | I36: 0 | J36: 0 | K36: 0 | L36: -93.56 | M36: 0 | N36: 0 | O36: =SUM(H36:N36) -> 356.26 | P36: 0 | Q36: 0 | R36: 0 | S36: 0 | T36: 0 | U36: 0 | V36: 0 | W36: =+O36+SUM(P36:V36) -> 356.26 | X36: =IF(W36>=0,W36,0) -> 356.26 | Y36: =IF(W36<=0,W36,0) -> 0 | Z36: 0 | AA36: =+Y36+Z36 -> 0 | AB36: =+O36-X36+Z36+AA36 -> 0 | AD36: =VLOOKUP($C36,'[1]CTRL AUTOS'!$E:$AH,2,0) -> MYE912A | AE36: =AD36&A36 -> MYE912A3
A37: 3 | B37: DIEGO SANCHEZ | C37: VENTO|2020|GRIS|R66BER | D37: OHLM023720329 | E37: ASHC | F37: ASHC | G37: UBER | H37: 4532.44 | I37: 0 | J37: 0 | K37: 0 | L37: -2041.45 | M37: -101.0688 | N37: 0 | O37: =SUM(H37:N37) -> 2389.9212 | P37: -2500 | Q37: 0 | R37: -500 | S37: 0 | T37: 0 | U37: 0 | V37: 0 | W37: =+O37+SUM(P37:V37) -> -610.0788 | X37: =IF(W37>=0,W37,0) -> 0 | Y37: =IF(W37<=0,W37,0) -> -610.0788 | Z37: 620 | AA37: =+Y37+Z37 -> 9.9212 | AB37: =+O37-X37+Z37+AA37 -> 3019.8424 | AC37: PAGADO | 21 ENE | AD37: =VLOOKUP($C37,'[1]CTRL AUTOS'!$E:$AH,2,0) -> R66BER | AE37: =AD37&A37 -> R66BER3
A38: 3 | B38: EDGAR GEOVANY URIBE | C38: AVEO|2019|PLATA|NEL860A | D38: OHLM023720337 | E38: ASHC | F38: ASHC | G38: UBER | H38: 5544.83 | I38: -101.6 | J38: 0 | K38: 0 | L38: -1756.2 | M38: -137.71245 | N38: 0 | O38: =SUM(H38:N38) -> 3549.3175 | P38: -2500 | Q38: 0 | R38: 0 | S38: -500 | T38: 0 | U38: 0 | V38: 0 | W38: =+O38+SUM(P38:V38) -> 549.31755 | X38: =IF(W38>=0,W38,0) -> 549.31755 | Y38: =IF(W38<=0,W38,0) -> 0 | Z38: 0 | AA38: =+Y38+Z38 -> 0 | AB38: =+O38-X38+Z38+AA38 -> 3000 | AD38: =VLOOKUP($C38,'[1]CTRL AUTOS'!$E:$AH,2,0) -> NEL860A | AE38: =AD38&A38 -> NEL860A3
A39: 3 | B39: FERNANDO ESQUIVEL SOSA | C39: VENTO|2018|AMARILLO|PED1652 | D39: OHLM031409055 | E39: ASHC | F39: ASHC | G39: UBER | H39: 7403.76 | I39: -138.4 | J39: 0 | K39: 0 | L39: -1056.42 | M39: -148.0752 | N39: 0 | O39: =SUM(H39:N39) -> 6060.8648 | P39: -1968 | Q39: 0 | R39: -500 | S39: 0 | T39: 0 | U39: 0 | V39: 0 | W39: =+O39+SUM(P39:V39) -> 3592.8648 | X39: =IF(W39>=0,W39,0) -> 3592.8648 | Y39: =IF(W39<=0,W39,0) -> 0 | Z39: 0 | AA39: =+Y39+Z39 -> 0 | AB39: =+O39-X39+Z39+AA39 -> 2468 | AD39: =VLOOKUP($C39,'[1]CTRL AUTOS'!$E:$AH,2,0) -> #N/A | AE39: =AD39&A39 -> #N/A
A40: 3 | B40: IRAM HERNANDEZ | C40: AVEO|2022|AZUL|MUF515A | D40: OHLM023720311 | E40: ASHC | F40: ASHC | G40: UBER | H40: 5136.53 | I40: -54.31 | J40: 0 | K40: 0 | L40: -1437.61 | M40: -77.04795 | N40: -55 | O40: =SUM(H40:N40) -> 3512.562 | P40: -2500 | Q40: 0 | R40: 0 | S40: -300 | T40: 0 | U40: 0 | V40: 0 | W40: =+O40+SUM(P40:V40) -> 712.56205 | X40: =IF(W40>=0,W40,0) -> 712.56205 | Y40: =IF(W40<=0,W40,0) -> 0 | Z40: 0 | AA40: =+Y40+Z40 -> 0 | AB40: =+O40-X40+Z40+AA40 -> 2800 | AD40: =VLOOKUP($C40,'[1]CTRL AUTOS'!$E:$AH,2,0) -> MUF515A | AE40: =AD40&A40 -> MUF515A3
...

Sheet UBER 2026
A1: SEM | B1: CONDUCTOR | C1: LLAVE | D1: TAG | E1: SOCIO | F1: PLATAFORMA | G1: APP | H1: GANANCIA | I1: EFECTIVO | J1: IMPUESTOS | K1: P. A ANT | L1: SEGURO | M1: P T | N1: TAG | O1: UBER GANANCIA | P1: RENTA | Q1: SEM PASADA | R1: FIANZA | S1: MULTA | T1: HOJALATERO | U1: DESCUENTOS | V1: PRÉSTAMOS | W1: TOTAL | X1: A PAGAR | Y1: DEV | Z1: PAGADO | AA1: ADEUDO | AB1: GANANCIAS TOTALES | AC1: Anticipo F | AD1: COMENTARIOS
A2: 1 | B2: ALEJANDRO PAZ CAMACHO | C2: MARCH|2020|TURQ|N15BKD | D2: OHLM038285789 | E2: =VLOOKUP(C2,'[2]CTRL AUTOS'!$E$2:$L$58,8,FALSE) -> ASHC | F2: =VLOOKUP(C2,'[2]CTRL AUTOS'!$E$2:$K$58,7,FALSE) -> ASHC | G2: DIDI | H2: 4784.74 | I2: -6209.03 | J2: -620 | K2: 0 | L2: 0 | M2: -95 | N2: 0 | O2: =IF(H2+I2<0,SUM(J2:N2),SUM(H2:N2)) -> -715 | P2: -2600 | Q2: -2771.97 | R2: 0 | S2: 0 | T2: 0 | U2: 0 | V2: 0 | W2: =SUM(O2:V2) -> -6086.97 | X2: =IF(W2>=0,W2,0) -> 0 | Y2: =IF(W2<=0,W2,0) -> -6086.97 | Z2: =800+2357 -> 3157 | AA2: =+Y2+Z2 -> -2929.97 | AB2: =+O2-X2+Z2+AA2 -> -487.97 | AD2: SE CONDONA ADEUDO Y SE AJUSTA DEUDO 2025
A3: 1 | B3: RAUL FRANCISCO VAZQUEZ CORTE | C3: V DRIVE|2023|GRIS|MXW453C | D3: OHLM038626776 | E3: =VLOOKUP(C3,'[2]CTRL AUTOS'!$E$2:$L$58,8,FALSE) -> ASHC | F3: =VLOOKUP(C3,'[2]CTRL AUTOS'!$E$2:$K$58,7,FALSE) -> ASHC | G3: DIDI | H3: 176.49 | I3: -130.25 | J3: -13 | K3: 0 | L3: 0 | M3: -65 | N3: 0 | O3: =IF(H3+I3<0,SUM(J3:N3),SUM(H3:N3)) -> -31.76 | P3: -2500 | Q3: -94 | R3: 0 | S3: 0 | T3: -500 | U3: 0 | V3: 0 | W3: =SUM(O3:V3) -> -3125.76 | X3: =IF(W3>=0,W3,0) -> 0 | Y3: =IF(W3<=0,W3,0) -> -3125.76 | Z3: 2800 | AA3: =+Y3+Z3 -> -325.76 | AB3: =+O3-X3+Z3+AA3 -> 2442.48 | AD3: DA RENTA POR FUERA HOJALATERIA 11/18, PAGA 2,800 11 ENE
A4: 1 | B4: FRANCISCO RODOLFO GOMEZ URQUIZA ESCALANTE | C4: KIA RIO|2020|AZUL|LUE960C | D4: OHLM035935635 | E4: ASHC | F4: ASHC | G4: DIDI | H4: 2721.77 | I4: -2373.6 | J4: -237 | K4: 0 | L4: 0 | M4: -95 | N4: 0 | O4: =IF(H4+I4<0,SUM(J4:N4),SUM(H4:N4)) -> 16.17 | P4: -2600 | Q4: 0 | R4: 0 | S4: 0 | T4: 0 | U4: 0 | V4: 0 | W4: =SUM(O4:V4) -> -2583.83 | X4: =IF(W4>=0,W4,0) -> 0 | Y4: =IF(W4<=0,W4,0) -> -2583.83 | Z4: 2857 | AA4: =+Y4+Z4 -> 273.17 | AB4: =+O4-X4+Z4+AA4 -> 3146.34 | AD4: TRABAJA DIDI-ASHC, PAGO 2,857 10 ENE (273 DE DIDI ATRASOS)
A5: 1 | B5: FRANCISCO ISLAS CHAVEZ | C5: AVEO|2024|GRIS|LRL009C | D5: OHLM032762171 | E5: =VLOOKUP(C5,'[2]CTRL AUTOS'!$E$2:$L$58,8,FALSE) -> ASHC | F5: =VLOOKUP(C5,'[2]CTRL AUTOS'!$E$2:$K$58,7,FALSE) -> ASHC | G5: DIDI | H5: 5249.01 | I5: -6142.27 | J5: -614 | K5: 0 | L5: 0 | M5: -95 | N5: 0 | O5: =IF(H5+I5<0,SUM(J5:N5),SUM(H5:N5)) -> -709 | P5: -2600 | Q5: 0 | R5: 0 | S5: 0 | T5: 0 | U5: 0 | V5: 0 | W5: =SUM(O5:V5) -> -3309 | X5: =IF(W5>=0,W5,0) -> 0 | Y5: =IF(W5<=0,W5,0) -> -3309 | Z5: =1200+1000 -> 2200 | AA5: =+Y5+Z5 -> -1109 | AB5: =+O5-X5+Z5+AA5 -> 382 | AD5: TRABAJA AMBAS APPS | PAGO 7 ENE 1,200 + 1,000 10 ENE GESTIONAR PAGO URGE
A6: 1 | B6: ADALBERTO BELLO NAVARRO | C6: AVEO|2025|PERSUASION|MXM510C | D6: OHLM038285821 | E6: =VLOOKUP(C6,'[2]CTRL AUTOS'!$E$2:$L$58,8,FALSE) -> ASHC | F6: =VLOOKUP(C6,'[2]CTRL AUTOS'!$E$2:$K$58,7,FALSE) -> ASHC | G6: UBER | H6: 8443.13 | I6: -5565.59 | J6: -20.8 | K6: 0 | L6: 0 | M6: -60 | N6: 0 | O6: =IF(H6+I6<0,SUM(J6:N6),SUM(H6:N6)) -> 2796.74 | P6: -2700 | Q6: 0 | R6: 0 | S6: 0 | T6: 0 | U6: 0 | V6: 0 | W6: =SUM(O6:V6) -> 96.74 | X6: =IF(W6>=0,W6,0) -> 96.74 | Y6: =IF(W6<=0,W6,0) -> 0 | Z6: 0 | AA6: =+Y6+Z6 -> 0 | AB6: =+O6-X6+Z6+AA6 -> 2700
A7: 1 | B7: ADRIAN CRUZ CUADROS | C7: AVEO|2025|PERSUASION|MXM503C | D7: OHLM038285813 | E7: =VLOOKUP(C7,'[2]CTRL AUTOS'!$E$2:$L$58,8,FALSE) -> ASHC | F7: =VLOOKUP(C7,'[2]CTRL AUTOS'!$E$2:$K$58,7,FALSE) -> ASHC | G7: UBER | H7: 6903.68 | I7: 0 | J7: -66.72 | K7: 19.58 | L7: 0 | M7: -77 | N7: -89 | O7: =IF(H7+I7<0,SUM(J7:N7),SUM(H7:N7)) -> 6690.54 | P7: -2700 | Q7: 0 | R7: 0 | S7: 0 | T7: 0 | U7: 0 | V7: 0 | W7: =SUM(O7:V7) -> 3990.54 | X7: =IF(W7>=0,W7,0) -> 3990.54 | Y7: =IF(W7<=0,W7,0) -> 0 | Z7: 0 | AA7: =+Y7+Z7 -> 0 | AB7: =+O7-X7+Z7+AA7 -> 2700
A8: 1 | B8: ALBERTO ARRIAGA MEJIA | C8: AVEO|2020|AZUL|D28BET | D8: OHLM032370140 | E8: =VLOOKUP(C8,'[2]CTRL AUTOS'!$E$2:$L$58,8,FALSE) -> ASHC | F8: =VLOOKUP(C8,'[2]CTRL AUTOS'!$E$2:$K$58,7,FALSE) -> ASHC | G8: UBER | H8: 1020.36 | I8: -59.93 | J8: -11.2 | K8: 0 | L8: 0 | M8: -63 | N8: -71 | O8: =IF(H8+I8<0,SUM(J8:N8),SUM(H8:N8)) -> 815.23 | P8: -2500 | Q8: 0 | R8: -500 | S8: 0 | T8: 0 | U8: 0 | V8: 0 | W8: =SUM(O8:V8) -> -2184.77 | X8: =IF(W8>=0,W8,0) -> 0 | Y8: =IF(W8<=0,W8,0) -> -2184.77 | Z8: =1100+1085 -> 2185 | AA8: =+Y8+Z8 -> 0.23 | AB8: =+O8-X8+Z8+AA8 -> 3000.46 | AD8: FIANZA 7/11 PAGO 7 ENE 1,100 + 1,085 8 ENE
A9: 1 | B9: ANGEL ALCANTARA CRUZ | C9: AVEO|2025|PERSUASION|MZN091C | D9: OHLM038626768 | E9: =VLOOKUP(C9,'[2]CTRL AUTOS'!$E$2:$L$58,8,FALSE) -> ASHC | F9: =VLOOKUP(C9,'[2]CTRL AUTOS'!$E$2:$K$58,7,FALSE) -> ASHC | G9: UBER | H9: 668.17 | I9: -29.99 | J9: -4.48 | K9: 0 | L9: 0 | M9: -60 | N9: 0 | O9: =IF(H9+I9<0,SUM(J9:N9),SUM(H9:N9)) -> 573.7 | P9: 0 | Q9: -737 | R9: 0 | S9: 0 | T9: 0 | U9: 0 | V9: 0 | W9: =SUM(O9:V9) -> -163.3 | X9: =IF(W9>=0,W9,0) -> 0 | Y9: =IF(W9<=0,W9,0) -> -163.3 | Z9: 0 | AA9: =+Y9+Z9 -> -163.3 | AB9: =+O9-X9+Z9+AA9 -> 410.4 | AD9: ADEUDO SEM ANT - PROB FAM HIJA LEUSEM PAGA EL LUNES SE CONDONA LA CUENTA
A10: 1 | B10: ARMANDO MARTINEZ VELAZQUEZ | C10: HYUNDAI|2022|PLATA|D40BKD | D10: OHLM023658024 | E10: =VLOOKUP(C10,'[2]CTRL AUTOS'!$E$2:$L$58,8,FALSE) -> ASHC | F10: =VLOOKUP(C10,'[2]CTRL AUTOS'!$E$2:$K$58,7,FALSE) -> ASHC | G10: UBER | H10: 922.84 | I10: 0 | J10: -4.48 | K10: 0 | L10: -8.49 | M10: -60 | N10: 0 | O10: =IF(H10+I10<0,SUM(J10:N10),SUM(H10:N10)) -> 849.87 | P10: -357.14286 | Q10: 0 | R10: 0 | S10: 0 | T10: -600 | U10: 0 | V10: 0 | W10: =SUM(O10:V10) -> -107.27286 | X10: =IF(W10>=0,W10,0) -> 0 | Y10: =IF(W10<=0,W10,0) -> -107.27286 | Z10: 0 | AA10: =+Y10+Z10 -> -107.27286 | AB10: =+O10-X10+Z10+AA10 -> 742.59714 | AD10: HOJALATERIA 2/5 PAGA HASTA LA SEM 3 SIN DESC DE HOJ
A11: 1 | B11: CAMILO IESUA MEJIA DIAZ | C11: KIA RIO|2020|GRIS|NCK475B | D11: OHLM032370124 | E11: =VLOOKUP(C11,'[2]CTRL AUTOS'!$E$2:$L$58,8,FALSE) -> ASHC | F11: =VLOOKUP(C11,'[2]CTRL AUTOS'!$E$2:$K$58,7,FALSE) -> ASHC | G11: UBER | H11: 2560.11 | I11: -491.67 | J11: -16.96 | K11: 106.1 | L11: 0 | M11: -60 | N11: 0 | O11: =IF(H11+I11<0,SUM(J11:N11),SUM(H11:N11)) -> 2097.58 | P11: -2500 | Q11: 0 | R11: -500 | S11: 0 | T11: 0 | U11: 0 | V11: 0 | W11: =SUM(O11:V11) -> -902.42 | X11: =IF(W11>=0,W11,0) -> 0 | Y11: =IF(W11<=0,W11,0) -> -902.42 | Z11: 902 | AA11: =+Y11+Z11 -> -0.42 | AB11: =+O11-X11+Z11+AA11 -> 2999.16 | AD11: FIANZA 5/10 PAGO 7 ENE 902
A12: 1 | B12: DAVID ARTURO GONZALEZ TELLEZ | C12: AVEO|2025|PERSUASION|MXM502C | D12: OHLM038285805 | E12: =VLOOKUP(C12,'[2]CTRL AUTOS'!$E$2:$L$58,8,FALSE) -> ASHC | F12: =VLOOKUP(C12,'[2]CTRL AUTOS'!$E$2:$K$58,7,FALSE) -> ASHC | G12: UBER | H12: 1605.6 | I12: -1702.64 | J12: -9.44 | K12: 0 | L12: 0 | M12: -86 | N12: -125.49 | O12: =IF(H12+I12<0,SUM(J12:N12),SUM(H12:N12)) -> -220.93 | P12: -771.42 | Q12: -4976 | R12: 0 | S12: 0 | T12: -700 | U12: 0 | V12: 0 | W12: =SUM(O12:V12) -> -6668.35 | X12: =IF(W12>=0,W12,0) -> 0 | Y12: =IF(W12<=0,W12,0) -> -6668.35 | Z12: =1000+1300+1000 -> 3300 | AA12: =+Y12+Z12 -> -3368.35 | AB12: =+O12-X12+Z12+AA12 -> -289.28 | AD12: CTA PROP 2 DIAS PQ SALIO CDMX,HOJALATERIA 11/26 - 1,300 9 ENE + 1,000 11 ENE 8ene 1000
A13: 1 | B13: FERNANDO FUENTES OTERO | C13: AVEOH|2024|BLANCO|MWV156C | D13: OHLM038626743 | E13: =VLOOKUP(C13,'[2]CTRL AUTOS'!$E$2:$L$58,8,FALSE) -> ASHC | F13: =VLOOKUP(C13,'[2]CTRL AUTOS'!$E$2:$K$58,7,FALSE) -> ASHC | G13: UBER | H13: 309.82 | I13: 0 | J13: 0 | K13: 0 | L13: 0 | M13: -60 | N13: 0 | O13: =IF(H13+I13<0,SUM(J13:N13),SUM(H13:N13)) -> 249.82 | P13: -2500 | Q13: -250 | R13: 0 | S13: 0 | T13: 0 | U13: 0 | V13: 0 | W13: =SUM(O13:V13) -> -2500.18 | X13: =IF(W13>=0,W13,0) -> 0 | Y13: =IF(W13<=0,W13,0) -> -2500.18 | Z13: =610+473+375+400+500+306 -> 2664 | AA13: =+Y13+Z13 -> 163.82 | AB13: =+O13-X13+Z13+AA13 -> 3077.64 | AD13: PAGO TRANSF ASHC 5 ENE 610, 473 9 ENE, 375 10 ENE, 400 10 ENE, 500 11 ENE, 306 11 ENE
A14: 1 | B14: FRANCISCO GOMEZ URQUIZA SILVA | C14: VERSA|2023|PLATA|NCT814A | D14: OHLM031491780 | E14: =VLOOKUP(C14,'[2]CTRL AUTOS'!$E$2:$L$58,8,FALSE) -> ASHC | F14: =VLOOKUP(C14,'[2]CTRL AUTOS'!$E$2:$K$58,7,FALSE) -> ASHC | G14: UBER | H14: 4543.72 | I14: -2246.92 | J14: -31.84 | K14: 0 | L14: 0 | M14: -65 | N14: 0 | O14: =IF(H14+I14<0,SUM(J14:N14),SUM(H14:N14)) -> 2199.96 | P14: -2500 | Q14: 0 | R14: -500 | S14: 0 | T14: 0 | U14: 0 | V14: 0 | W14: =SUM(O14:V14) -> -800.04 | X14: =IF(W14>=0,W14,0) -> 0 | Y14: =IF(W14<=0,W14,0) -> -800.04 | Z14: 800 | AA14: =+Y14+Z14 -> -0.04 | AB14: =+O14-X14+Z14+AA14 -> 2999.92 | AD14: FIANZA 5/10 - PAGO 800 6 ENE
A15: 1 | B15: FRANCISCO ISLAS CHAVEZ | C15: AVEO|2024|GRIS|LRL009C | D15: OHLM032762171 | E15: =VLOOKUP(C15,'[2]CTRL AUTOS'!$E$2:$L$58,8,FALSE) -> ASHC | F15: =VLOOKUP(C15,'[2]CTRL AUTOS'!$E$2:$K$58,7,FALSE) -> ASHC | G15: UBER | H15: 95.23 | I15: -80.21 | J15: 0 | K15: 0 | L15: 0 | M15: -15 | N15: 0 | O15: =IF(H15+I15<0,SUM(J15:N15),SUM(H15:N15)) -> 0.02 | P15: 0 | Q15: 0 | R15: 0 | S15: 0 | T15: 0 | U15: 0 | V15: 0 | W15: =SUM(O15:V15) -> 0.02 | X15: =IF(W15>=0,W15,0) -> 0.02 | Y15: =IF(W15<=0,W15,0) -> 0 | Z15: 0 | AA15: =+Y15+Z15 -> 0 | AB15: =+O15-X15+Z15+AA15 -> 0 | AD15: SE COBRA CTA COMPL EN DIDI
A16: 1 | B16: GERMAN LUSARRETA ROMERO | C16: AVEO|2021|GRIS|D51BHV | D16: OHLM037480324 | E16: =VLOOKUP(C16,'[2]CTRL AUTOS'!$E$2:$L$58,8,FALSE) -> ASHC | F16: =VLOOKUP(C16,'[2]CTRL AUTOS'!$E$2:$K$58,7,FALSE) -> ASHC | G16: UBER | H16: 5101.6 | I16: -1716.25 | J16: -23.84 | K16: 311.99 | L16: 0 | M16: -66.5 | N16: -25.87 | O16: =IF(H16+I16<0,SUM(J16:N16),SUM(H16:N16)) -> 3581.13 | P16: -2500 | Q16: 0 | R16: -500 | S16: 0 | T16: 0 | U16: 0 | V16: 0 | W16: =SUM(O16:V16) -> 581.13 | X16: =IF(W16>=0,W16,0) -> 581.13 | Y16: =IF(W16<=0,W16,0) -> 0 | Z16: 0 | AA16: =+Y16+Z16 -> 0 | AB16: =+O16-X16+Z16+AA16 -> 3000 | AD16: FIANZA 6/11
A17: 1 | B17: JESUS ROSALES GARCIA | C17: AVEOH|2026|ACERO|NEJ996C | D17: SIN TAG | E17: =VLOOKUP(C17,'[2]CTRL AUTOS'!$E$2:$L$58,8,FALSE) -> ASHC | F17: =VLOOKUP(C17,'[2]CTRL AUTOS'!$E$2:$K$58,7,FALSE) -> ASHC | G17: UBER | H17: 10752.02 | I17: -5054.19 | J17: -36.48 | K17: 0 | L17: 0 | M17: -65 | N17: 0 | O17: =IF(H17+I17<0,SUM(J17:N17),SUM(H17:N17)) -> 5596.35 | P17: =-357.14-2314.28 -> -2671.42 | Q17: 0 | R17: -500 | S17: 0 | T17: 0 | U17: 0 | V17: 0 | W17: =SUM(O17:V17) -> 2424.93 | X17: =IF(W17>=0,W17,0) -> 2424.93 | Y17: =IF(W17<=0,W17,0) -> 0 | Z17: 0 | AA17: =+Y17+Z17 -> 0 | AB17: =+O17-X17+Z17+AA17 -> 3171.42 | AD17: CTA PROPDEL LUNES 2,500, RESTO DE SEM 2700
A18: 1 | B18: JONATHAN BERNAL RODRIGUEZ | C18: AVEO|2018|GRIS|X59AWG | D18: OHLM031409063 | E18: =VLOOKUP(C18,'[2]CTRL AUTOS'!$E$2:$L$58,8,FALSE) -> ASHC | F18: =VLOOKUP(C18,'[2]CTRL AUTOS'!$E$2:$K$58,7,FALSE) -> ASHC | G18: UBER | H18: 2245.26 | I18: -363.75 | J18: 0 | K18: 0 | L18: -24.09 | M18: -140 | N18: -378.18 | O18: =IF(H18+I18<0,SUM(J18:N18),SUM(H18:N18)) -> 1339.24 | P18: -2500 | Q18: -627 | R18: -500 | S18: 0 | T18: 0 | U18: 0 | V18: 0 | W18: =SUM(O18:V18) -> -2287.76 | X18: =IF(W18>=0,W18,0) -> 0 | Y18: =IF(W18<=0,W18,0) -> -2287.76 | Z18: 1800 | AA18: =+Y18+Z18 -> -487.76 | AB18: =+O18-X18+Z18+AA18 -> 2651.48 | AD18: PAGA 1,800 10 ENE
A19: 1 | B19: JOSE GUILLERMO HERNANDEZ RAMIREZ | C19: AVEO|2023|GRIS|MLC126A | D19: OHLM037480332 | E19: =VLOOKUP(C19,'[2]CTRL AUTOS'!$E$2:$L$58,8,FALSE) -> ASHC | F19: =VLOOKUP(C19,'[2]CTRL AUTOS'!$E$2:$K$58,7,FALSE) -> ASHC | G19: UBER | H19: 7594.7 | I19: -3449.65 | J19: -36.48 | K19: 0 | L19: 0 | M19: -65 | N19: 0 | O19: =IF(H19+I19<0,SUM(J19:N19),SUM(H19:N19)) -> 4043.57 | P19: -1250 | Q19: -360 | R19: 0 | S19: 0 | T19: 0 | U19: 0 | V19: 0 | W19: =SUM(O19:V19) -> 2433.57 | X19: =IF(W19>=0,W19,0) -> 2433.57 | Y19: =IF(W19<=0,W19,0) -> 0 | Z19: 0 | AA19: =+Y19+Z19 -> 0 | AB19: =+O19-X19+Z19+AA19 -> 1610 | AD19: REDUCCION DE CTA 1/2
A20: 1 | B20: JOSE JUAN HERNANDEZ MEJIA | C20: VENTO|2020|GRIS|A19BDY | D20: OHLM038626750 | E20: =VLOOKUP(C20,'[2]CTRL AUTOS'!$E$2:$L$58,8,FALSE) -> ASHC | F20: =VLOOKUP(C20,'[2]CTRL AUTOS'!$E$2:$K$58,7,FALSE) -> ASHC | G20: UBER | H20: 7690.57 | I20: -3610.68 | J20: -76.96 | K20: 0 | L20: 0 | M20: -65 | N20: 0 | O20: =IF(H20+I20<0,SUM(J20:N20),SUM(H20:N20)) -> 3937.93 | P20: -2500 | Q20: -210 | R20: 0 | S20: 0 | T20: 0 | U20: 0 | V20: 0 | W20: =SUM(O20:V20) -> 1227.93 | X20: =IF(W20>=0,W20,0) -> 1227.93 | Y20: =IF(W20<=0,W20,0) -> 0 | Z20: 0 | AA20: =+Y20+Z20 -> 0 | AB20: =+O20-X20+Z20+AA20 -> 2710
A21: 1 | B21: JUAN CARLOS ZEA CRUZ | C21: AVEO|2019|PLATA|NEL860A | D21: OHLM032370132 | E21: =VLOOKUP(C21,'[2]CTRL AUTOS'!$E$2:$L$58,8,FALSE) -> ASHC | F21: =VLOOKUP(C21,'[2]CTRL AUTOS'!$E$2:$K$58,7,FALSE) -> ASHC | G21: UBER | H21: 2373.01 | I21: -218.08 | J21: 0 | K21: 0 | L21: 0 | M21: -60 | N21: 0 | O21: =IF(H21+I21<0,SUM(J21:N21),SUM(H21:N21)) -> 2094.93 | P21: -2500 | Q21: 0 | R21: -500 | S21: 0 | T21: 0 | U21: 0 | V21: 0 | W21: =SUM(O21:V21) -> -905.07 | X21: =IF(W21>=0,W21,0) -> 0 | Y21: =IF(W21<=0,W21,0) -> -905.07 | Z21: 605 | AA21: =+Y21+Z21 -> -300.07 | AB21: =+O21-X21+Z21+AA21 -> 2399.86 | AD21: FIANZA 3/11 PAGO 7 ENE 605 NO CONTESTA
A22: 1 | B22: KRISTOPHER ALEXANDER TORREALBA RAMOS | C22: VENTO|2017|GRIS|MMA672C | D22: OHLM023720279 | E22: =VLOOKUP(C22,'[2]CTRL AUTOS'!$E$2:$L$58,8,FALSE) -> ASHC | F22: =VLOOKUP(C22,'[2]CTRL AUTOS'!$E$2:$K$58,7,FALSE) -> ASHC | G22: UBER | H22: 3703.3 | I22: -2282.87 | J22: 0 | K22: 0 | L22: 0 | M22: -60 | N22: 0 | O22: =IF(H22+I22<0,SUM(J22:N22),SUM(H22:N22)) -> 1360.43 | P22: -1360 | Q22: 0 | R22: 0 | S22: 0 | T22: 0 | U22: 0 | V22: 0 | W22: =SUM(O22:V22) -> 0.43 | X22: =IF(W22>=0,W22,0) -> 0.43 | Y22: =IF(W22<=0,W22,0) -> 0 | Z22: 0 | AA22: =+Y22+Z22 -> 0 | AB22: =+O22-X22+Z22+AA22 -> 1360 | AD22: CTA PROPAL JUEVES, ABANDONA AUTO, NO SE LE REGRESA FIANZA NI PAGO.
A23: 1 | B23: MARCO ANTONIO FARIAS AVILES | C23: BEAT|2019|OCRE|MAY730C | D23: OHLM036759058 | E23: =VLOOKUP(C23,'[2]CTRL AUTOS'!$E$2:$L$58,8,FALSE) -> ASHC | F23: =VLOOKUP(C23,'[2]CTRL AUTOS'!$E$2:$K$58,7,FALSE) -> ASHC | G23: UBER | H23: 1577.88 | I23: 0 | J23: -9.28 | K23: 0 | L23: 0 | M23: -65 | N23: 0 | O23: =IF(H23+I23<0,SUM(J23:N23),SUM(H23:N23)) -> 1503.6 | P23: -2500 | Q23: -76 | R23: -500 | S23: 0 | T23: 0 | U23: 0 | V23: 0 | W23: =SUM(O23:V23) -> -1572.4 | X23: =IF(W23>=0,W23,0) -> 0 | Y23: =IF(W23<=0,W23,0) -> -1572.4 | Z23: =1000+500 -> 1500 | AA23: =+Y23+Z23 -> -72.4 | AB23: =+O23-X23+Z23+AA23 -> 2931.2 | AD23: FIANZA 3/10 PAGO 7 ENE 1,000 Y 500 11 ENE
A24: 1 | B24: OSCAR BLANCAS NORIEGA | C24: VENTO|2020|GRIS|R66BER | D24: OHLM023720329 | E24: =VLOOKUP(C24,'[2]CTRL AUTOS'!$E$2:$L$58,8,FALSE) -> ASHC | F24: =VLOOKUP(C24,'[2]CTRL AUTOS'!$E$2:$K$58,7,FALSE) -> ASHC | G24: UBER | H24: 2073.67 | I24: -619.58 | J24: -14.4 | K24: 0 | L24: 0 | M24: -11 | N24: 0 | O24: =IF(H24+I24<0,SUM(J24:N24),SUM(H24:N24)) -> 1428.69 | P24: -1428.57 | Q24: 0 | R24: 0 | S24: 0 | T24: 0 | U24: 0 | V24: 0 | W24: =SUM(O24:V24) -> 0.12 | X24: =IF(W24>=0,W24,0) -> 0.12 | Y24: =IF(W24<=0,W24,0) -> 0 | Z24: 0 | AA24: =+Y24+Z24 -> 0 | AB24: =+O24-X24+Z24+AA24 -> 1428.57 | AD24: CTA PROP 4 DÍAS, SE BAJA VIE, ADEUDA HOJTRIA, LLAVE, Y LAV INTER (SIN DEV DE FIANZA)
A25: 1 | B25: RAYMUNDO CHAVEZ DELGADO | C25: AVEOH|2026|ACERO|NEJ971C | D25: SIN TAG | E25: =VLOOKUP(C25,'[2]CTRL AUTOS'!$E$2:$L$58,8,FALSE) -> ASHC | F25: =VLOOKUP(C25,'[2]CTRL AUTOS'!$E$2:$K$58,7,FALSE) -> ASHC | G25: UBER | H25: 3451.27 | I25: -1775.14 | J25: -16.96 | K25: 127.04 | L25: -42.97 | M25: -65 | N25: 0 | O25: =IF(H25+I25<0,SUM(J25:N25),SUM(H25:N25)) -> 1678.24 | P25: =-357.14-2314.28 -> -2671.42 | Q25: 0 | R25: -500 | S25: 0 | T25: 0 | U25: 0 | V25: 0 | W25: =SUM(O25:V25) -> -1493.18 | X25: =IF(W25>=0,W25,0) -> 0 | Y25: =IF(W25<=0,W25,0) -> -1493.18 | Z25: 0 | AA25: =+Y25+Z25 -> -1493.18 | AB25: =+O25-X25+Z25+AA25 -> 185.06 | AD25: CTA LUNES 2,500, MAR-DOM 2700, FIANZA 10/10 - QUEDA CON ROUS PAGO EN DOS EXHIBISIONES S2 746.5 Y S3 746.5 +12%
A26: 1 | B26: RICARDO HERNANDEZ ARIAS | C26: AVEO|2019|BLANCO|NBS225A | D26: OHLM038285797 | E26: =VLOOKUP(C26,'[2]CTRL AUTOS'!$E$2:$L$58,8,FALSE) -> ASHC | F26: =VLOOKUP(C26,'[2]CTRL AUTOS'!$E$2:$K$58,7,FALSE) -> ASHC | G26: UBER | H26: 7279.62 | I26: -277.08 | J26: -42.02 | K26: -5.32 | L26: 0 | M26: -65 | N26: 0 | O26: =IF(H26+I26<0,SUM(J26:N26),SUM(H26:N26)) -> 6890.2 | P26: -2500 | Q26: 0 | R26: 0 | S26: 0 | T26: -700 | U26: 0 | V26: 0 | W26: =SUM(O26:V26) -> 3690.2 | X26: =IF(W26>=0,W26,0) -> 3690.2 | Y26: =IF(W26<=0,W26,0) -> 0 | Z26: 0 | AA26: =+Y26+Z26 -> 0 | AB26: =+O26-X26+Z26+AA26 -> 3200 | AD26: HOJALATERIA 11/23
A27: 1 | B27: SAUL DOMINGUEZ VAZQUEZ | C27: VERSA|2020|BLANCO|A35BHD | D27: OHLM032370082 | E27: =VLOOKUP(C27,'[2]CTRL AUTOS'!$E$2:$L$58,8,FALSE) -> ASHC | F27: =VLOOKUP(C27,'[2]CTRL AUTOS'!$E$2:$K$58,7,FALSE) -> ASHC | G27: UBER | H27: 2853.66 | I27: -428.05 | J27: -34.56 | K27: 0 | L27: -23.35 | M27: -60 | N27: 0 | O27: =IF(H27+I27<0,SUM(J27:N27),SUM(H27:N27)) -> 2307.7 | P27: -2500 | Q27: 0 | R27: 0 | S27: 0 | T27: 0 | U27: 0 | V27: 0 | W27: =SUM(O27:V27) -> -192.3 | X27: =IF(W27>=0,W27,0) -> 0 | Y27: =IF(W27<=0,W27,0) -> -192.3 | Z27: 192 | AA27: =+Y27+Z27 -> -0.3 | AB27: =+O27-X27+Z27+AA27 -> 2499.4 | AD27: PAGA 192 6 ENE
A28: 1 | B28: SERGIO BALDERAS BAEZ | C28: AVEO|2022|AZUL|NZY685B | D28: OHLM032370116 | E28: =VLOOKUP(C28,'[2]CTRL AUTOS'!$E$2:$L$58,8,FALSE) -> ASHC | F28: =VLOOKUP(C28,'[2]CTRL AUTOS'!$E$2:$K$58,7,FALSE) -> ASHC | G28: UBER | H28: 5549.21 | I28: -1856.39 | J28: -18.88 | K28: 0 | L28: 0 | M28: -65 | N28: 0 | O28: =IF(H28+I28<0,SUM(J28:N28),SUM(H28:N28)) -> 3608.94 | P28: -2500 | Q28: 0 | R28: -500 | S28: 0 | T28: 0 | U28: -1000 | V28: 0 | W28: =SUM(O28:V28) -> -391.06 | X28: =IF(W28>=0,W28,0) -> 0 | Y28: =IF(W28<=0,W28,0) -> -391.06 | Z28: 391 | AA28: =+Y28+Z28 -> -0.06 | AB28: =+O28-X28+Z28+AA28 -> 3999.88 | AD28: FIANZA 7/10, PAGA ADEUDO 2/2 | PAGO 7 ENE 391
A29: 1 | B29: YOSHUA JARETH VALDEZ HERNANDEZ | C29: KIA RIO|2017|ROJO|MYE912A | D29: OHLM032762130 | E29: =VLOOKUP(C29,'[2]CTRL AUTOS'!$E$2:$L$58,8,FALSE) -> U64 | F29: =VLOOKUP(C29,'[2]CTRL AUTOS'!$E$2:$K$58,7,FALSE) -> BYER | G29: UBER | H29: 1169.28 | I29: -370.52 | J29: -4.48 | K29: 0 | L29: 0 | M29: -65 | N29: 0 | O29: =IF(H29+I29<0,SUM(J29:N29),SUM(H29:N29)) -> 729.28 | P29: -2500 | Q29: 871 | R29: 0 | S29: 0 | T29: 0 | U29: 0 | V29: 0 | W29: =SUM(O29:V29) -> -899.72 | X29: =IF(W29>=0,W29,0) -> 0 | Y29: =IF(W29<=0,W29,0) -> -899.72 | Z29: 900 | AA29: =+Y29+Z29 -> 0.28 | AB29: =+O29-X29+Z29+AA29 -> 1629.56 | AD29: SEM 817 A FAVOR, ADEUDO DE GOLPE 2018, $5000 SEMANALES - DEPOSITA 3,000 6 ENE (900 A CUENTA Y 2,100 GLPE PED)
A30: 1 | B30: JOSE AGUILAR SOTO | C30: AVEO|2020|AZUL|D28BET | D30: OHLM032370140 | E30: =VLOOKUP(C30,'[2]CTRL AUTOS'!$E$2:$L$58,8,FALSE) -> ASHC | F30: =VLOOKUP(C30,'[2]CTRL AUTOS'!$E$2:$K$58,7,FALSE) -> ASHC | G30: UBER | H30: 0 | I30: 0 | J30: 0 | K30: 0 | L30: 0 | M30: 0 | N30: 0 | O30: =IF(H30+I30<0,SUM(J30:N30),SUM(H30:N30)) -> 0 | P30: 0 | Q30: 0 | R30: 500 | S30: 0 | T30: 0 | U30: 0 | V30: 0 | W30: =SUM(O30:V30) -> 500 | X30: =IF(W30>=0,W30,0) -> 500 | Y30: =IF(W30<=0,W30,0) -> 0 | Z30: 0 | AA30: =+Y30+Z30 -> 0 | AB30: =+O30-X30+Z30+AA30 -> -500 | AD30: DEV FIANZA 7/10
A31: 1 | B31: RUBEN BERMEJO | C31: AVEO|2022|VINO|P62BHW | D31: OHLM037480340 | E31: =VLOOKUP(C31,'[2]CTRL AUTOS'!$E$2:$L$58,8,FALSE) -> ASHC | F31: BYER | G31: UBER | H31: 0 | I31: 0 | J31: 0 | K31: 0 | L31: 0 | M31: 0 | N31: 0 | O31: =IF(H31+I31<0,SUM(J31:N31),SUM(H31:N31)) -> 0 | P31: 0 | Q31: 0 | R31: 500 | S31: 0 | T31: 0 | U31: 0 | V31: 0 | W31: =SUM(O31:V31) -> 500 | X31: =IF(W31>=0,W31,0) -> 500 | Y31: =IF(W31<=0,W31,0) -> 0 | Z31: 0 | AA31: =+Y31+Z31 -> 0 | AB31: =+O31-X31+Z31+AA31 -> -500 | AD31: ULTIMO PAGO DE FIANZA
A32: 1 | B32: FIDEL ALEJANDRO SANCHEZ VERGARA | C32: VERSA|2023|PLATA|NCT814A | D32: OHLM031491780 | E32: =VLOOKUP(C32,'[2]CTRL AUTOS'!$E$2:$L$58,8,FALSE) -> ASHC | F32: =VLOOKUP(C32,'[2]CTRL AUTOS'!$E$2:$K$58,7,FALSE) -> ASHC | G32: UBER | H32: 0 | I32: 0 | J32: 0 | K32: 0 | L32: 0 | M32: 0 | N32: 0 | O32: =IF(H32+I32<0,SUM(J32:N32),SUM(H32:N32)) -> 0 | P32: 0 | Q32: 0 | R32: 500 | S32: 0 | T32: 0 | U32: 0 | V32: 0 | W32: =SUM(O32:V32) -> 500 | X32: =IF(W32>=0,W32,0) -> 500 | Y32: =IF(W32<=0,W32,0) -> 0 | Z32: 0 | AA32: =+Y32+Z32 -> 0 | AB32: =+O32-X32+Z32+AA32 -> -500 | AD32: DEV DE FIANZA 3/7
A33: 1 | B33: JOSE LUIS HERNANDEZ MEDINA | C33: AVEO|2018|GRIS|X59AWG | D33: OHLM031409063 | E33: =VLOOKUP(C33,'[2]CTRL AUTOS'!$E$2:$L$58,8,FALSE) -> ASHC | F33: =VLOOKUP(C33,'[2]CTRL AUTOS'!$E$2:$K$58,7,FALSE) -> ASHC | G33: UBER | H33: 0 | I33: 0 | J33: 0 | K33: 0 | L33: 0 | M33: 0 | N33: 0 | O33: =IF(H33+I33<0,SUM(J33:N33),SUM(H33:N33)) -> 0 | P33: 0 | Q33: 0 | R33: 0 | S33: 0 | T33: -700 | U33: 0 | V33: 0 | W33: =SUM(O33:V33) -> -700 | X33: =IF(W33>=0,W33,0) -> 0 | Y33: =IF(W33<=0,W33,0) -> -700 | Z33: 700 | AA33: =+Y33+Z33 -> 0 | AB33: =+O33-X33+Z33+AA33 -> 700 | AD33: TRABAJA APP JG UBER, HOJALATERIA 12/15 - PAGA 700 7 ENE
A34: 1 | B34: ALFONSO GONZALEZ MORALES | C34: SWIFT|2017|ROJO|X89ALV | D34: OHLM032370090 | E34: =VLOOKUP(C34,'[2]CTRL AUTOS'!$E$2:$L$58,8,FALSE) -> BYER | F34: =VLOOKUP(C34,'[2]CTRL AUTOS'!$E$2:$K$58,7,FALSE) -> BYER | G34: UBER | H34: 5950.53 | I34: -2088.56 | J34: -14.4 | K34: 14.69 | L34: 0 | M34: -62 | N34: 0 | O34: =IF(H34+I34<0,SUM(J34:N34),SUM(H34:N34)) -> 3800.26 | P34: -2500 | Q34: -600 | R34: 0 | S34: 0 | T34: -700 | U34: 0 | V34: 0 | W34: =SUM(O34:V34) -> 0.26 | X34: =IF(W34>=0,W34,0) -> 0.26 | Y34: =IF(W34<=0,W34,0) -> 0 | Z34: 0 | AA34: =+Y34+Z34 -> 0 | AB34: =+O34-X34+Z34+AA34 -> 3800 | AD34: ADEUDO SEMANA PASADA A 12%,HOJALATERIA 7/8
A35: 1 | B35: CRISTIAN HERNANDEZ MUNGUIA | C35: AVEOH|2026|ACERO|NEJ990C | D35: SIN TAG | E35: =VLOOKUP(C35,'[2]CTRL AUTOS'!$E$2:$L$58,8,FALSE) -> ASHC | F35: =VLOOKUP(C35,'[2]CTRL AUTOS'!$E$2:$K$58,7,FALSE) -> ASHC | G35: UBER | H35: 5116.35 | I35: -556.69 | J35: -11.68 | K35: 0 | L35: 0 | M35: -60 | N35: 0 | O35: =IF(H35+I35<0,SUM(J35:N35),SUM(H35:N35)) -> 4487.98 | P35: -1764.42 | Q35: 0 | R35: -500 | S35: 0 | T35: 0 | U35: 0 | V35: 0 | W35: =SUM(O35:V35) -> 2223.56 | X35: =IF(W35>=0,W35,0) -> 2223.56 | Y35: =IF(W35<=0,W35,0) -> 0 | Z35: 0 | AA35: =+Y35+Z35 -> 0 | AB35: =+O35-X35+Z35+AA35 -> 2264.42 | AD35: CTA PROP TRABAJO EN PLAT 1 DÍA 2,500 SEM RESTANTE 2,700.. FIANZA 6/11
A36: 1 | B36: EDUARDO LICONA GODINEZ | C36: KIA RIO|2020|ROJO|MFP751C | D36: OHLM036759090 | E36: =VLOOKUP(C36,'[2]CTRL AUTOS'!$E$2:$L$58,8,FALSE) -> ASHC | F36: =VLOOKUP(C36,'[2]CTRL AUTOS'!$E$2:$K$58,7,FALSE) -> ASHC | G36: UBER | H36: 5671.6 | I36: -4668.93 | J36: -18.88 | K36: 11.27 | L36: -64.21 | M36: -65 | N36: 0 | O36: =IF(H36+I36<0,SUM(J36:N36),SUM(H36:N36)) -> 865.85 | P36: -2500 | Q36: 6 | R36: -500 | S36: 0 | T36: 0 | U36: 0 | V36: 0 | W36: =SUM(O36:V36) -> -2128.15 | X36: =IF(W36>=0,W36,0) -> 0 | Y36: =IF(W36<=0,W36,0) -> -2128.15 | Z36: 2128 | AA36: =+Y36+Z36 -> -0.15 | AB36: =+O36-X36+Z36+AA36 -> 2993.7 | AD36: FIANZA 4/9 - PAGA 2,182 7 ENE
A37: 1 | B37: FERNANDO GARRIDO GARNICA | C37: AVEO|2018|ROJO|R51BKD | D37: OHLM032762106 | E37: =VLOOKUP(C37,'[2]CTRL AUTOS'!$E$2:$L$58,8,FALSE) -> U64 | F37: =VLOOKUP(C37,'[2]CTRL AUTOS'!$E$2:$K$58,7,FALSE) -> BYER | G37: UBER | H37: 5154.64 | I37: -2256.03 | J37: -17.28 | K37: 0 | L37: 0 | M37: -65 | N37: 0 | O37: =IF(H37+I37<0,SUM(J37:N37),SUM(H37:N37)) -> 2816.33 | P37: -2500 | Q37: 0 | R37: -500 | S37: 0 | T37: 0 | U37: 0 | V37: 0 | W37: =SUM(O37:V37) -> -183.67 | X37: =IF(W37>=0,W37,0) -> 0 | Y37: =IF(W37<=0,W37,0) -> -183.67 | Z37: 0 | AA37: =+Y37+Z37 -> -183.67 | AB37: =+O37-X37+Z37+AA37 -> 2632.66 | AD37: FIANZA 4/11
A38: 1 | B38: GABRIEL JIMENEZ BAUTISTA | C38: BYD|2026|VERDE|78F032 | D38: OHLM038628194 | E38: =VLOOKUP(C38,'[2]CTRL AUTOS'!$E$2:$L$58,8,FALSE) -> ASHC | F38: BYER | G38: UBER | H38: 2648.45 | I38: 0 | J38: -26.08 | K38: 0 | L38: 0 | M38: 0 | N38: 0 | O38: =IF(H38+I38<0,SUM(J38:N38),SUM(H38:N38)) -> 2622.37 | P38: -2622 | Q38: 0 | R38: 0 | S38: 0 | T38: 0 | U38: 0 | V38: 0 | W38: =SUM(O38:V38) -> 0.37 | X38: =IF(W38>=0,W38,0) -> 0.37 | Y38: =IF(W38<=0,W38,0) -> 0 | Z38: 0 | AA38: =+Y38+Z38 -> 0 | AB38: =+O38-X38+Z38+AA38 -> 2622 | AD38: OPERACION
A39: 1 | B39: IVAN MOGUEL PULIDO | C39: KIA RIO|2023|ROJO|H99BLC | D39: OHLM035993526 | E39: =VLOOKUP(C39,'[2]CTRL AUTOS'!$E$2:$L$58,8,FALSE) -> U64 | F39: =VLOOKUP(C39,'[2]CTRL AUTOS'!$E$2:$K$58,7,FALSE) -> BYER | G39: UBER | H39: 6575.11 | I39: -4131.59 | J39: -14.88 | K39: 0 | L39: -65.54 | M39: -65 | N39: 0 | O39: =IF(H39+I39<0,SUM(J39:N39),SUM(H39:N39)) -> 2298.1 | P39: -1250 | Q39: 0 | R39: 0 | S39: 0 | T39: 0 | U39: 0 | V39: 0 | W39: =SUM(O39:V39) -> 1048.1 | X39: =IF(W39>=0,W39,0) -> 1048.1 | Y39: =IF(W39<=0,W39,0) -> 0 | Z39: 0 | AA39: =+Y39+Z39 -> 0 | AB39: =+O39-X39+Z39+AA39 -> 1250 | AD39: REDUCCION DE CTA 1/2
A40: 1 | B40: RUBI ROBLES SALMERON | C40: BEAT|2020|GRIS|NFN014B | D40: OHLM032762148 | E40: =VLOOKUP(C40,'[2]CTRL AUTOS'!$E$2:$L$58,8,FALSE) -> U64 | F40: =VLOOKUP(C40,'[2]CTRL AUTOS'!$E$2:$K$58,7,FALSE) -> BYER | G40: UBER | H40: 4207.92 | I40: -1148.34 | J40: -18.88 | K40: 0 | L40: 0 | M40: -65 | N40: 0 | O40: =IF(H40+I40<0,SUM(J40:N40),SUM(H40:N40)) -> 2975.7 | P40: -2500 | Q40: -679 | R40: 0 | S40: 0 | T40: -500 | U40: 0 | V40: 0 | W40: =SUM(O40:V40) -> -703.3 | X40: =IF(W40>=0,W40,0) -> 0 | Y40: =IF(W40<=0,W40,0) -> -703.3 | Z40: =503+200 -> 703 | AA40: =+Y40+Z40 -> -0.3 | AB40: =+O40-X40+Z40+AA40 -> 3678.4 | AD40: HOJALATERIA 7/18,PROMESA DE PAGO DIA MARTES NO CONTESTA. PAGA 503 10 ENE Y 200 11 ENE
...

Sheet CONDUCTORES
B1: SEM | C1: CONDUCTOR | D1: AUTO | E1: ASHC
B2: 1 | C2: ALEJANDRO PAZ CAMACHO | D2: MARCH|2020|TURQ|N15BKD | E2: ASHC
B3: 1 | C3: RAUL FRANCISCO VAZQUEZ CORTE | D3: V DRIVE|2023|GRIS|MXW453C | E3: ASHC
B4: 1 | C4: FRANCISCO RODOLFO GOMEZ URQUIZA ESCALANTE | D4: KIA RIO|2020|AZUL|LUE960C | E4: U64
B5: 1 | C5: FRANCISCO ISLAS CHAVEZ | D5: AVEO|2024|GRIS|LRL009C | E5: ASHC
B6: 1 | C6: ADALBERTO BELLO NAVARRO | D6: AVEO|2025|PERSUASION|MXM510C | E6: ASHC
B7: 1 | C7: ADRIAN CRUZ CUADROS | D7: AVEO|2025|PERSUASION|MXM503C | E7: ASHC
B8: 1 | C8: ALBERTO ARRIAGA MEJIA | D8: AVEO|2020|AZUL|D28BET | E8: ASHC
B9: 1 | C9: ANGEL ALCANTARA CRUZ | D9: AVEO|2025|PERSUASION|MZN091C | E9: ASHC
B10: 1 | C10: ARMANDO MARTINEZ VELAZQUEZ | D10: HYUNDAI|2022|PLATA|D40BKD | E10: ASHC
B11: 1 | C11: CAMILO IESUA MEJIA DIAZ | D11: KIA RIO|2020|GRIS|NCK475B | E11: ASHC
B12: 1 | C12: DAVID ARTURO GONZALEZ TELLEZ | D12: AVEO|2025|PERSUASION|MXM502C | E12: U64
B13: 1 | C13: FERNANDO FUENTES OTERO | D13: AVEOH|2024|BLANCO|MWV156C | E13: ASHC
... B474: 8 | C474: FERNANDO OSORNIO VILLASANA | D474: AVEO|2019|PLATA|NEL860A | E474: ASHC
B475: 8 | C475: ULISES SANCHEZ HERNANDEZ | E475: ASHC
B476: 9 | C476: ALEJANDRO VELAZQUEZ VARGAS | D476: AVEO|2022|AZUL|NZY685B | E476: ASHC
B477: 9 | C477: JOSE LUIS PEDRAZA AVILA | D477: AVEO|2019|PLATA|NEL860A | E477: JGD
B478: 9 | C478: ALAN AURELIO ORTEGA ORDOÑEZ | D478: BEAT|2019|OCRE|MAY730C | E478: ASHC
B479: 9 | C479: EMILIANO SOLANO SALAZAR | D479: AVEO|2019|BLANCO|NBS225A | E479: ASHC
B480: 9 | C480: EMILIANO SOLANO SALAZAR | D480: AVEOH|2026|ROJO|NEZ101C | E480: ASHC
B481: 9 | C481: RAUL NABOR MORIN MEJIA | D481: AVEO|2018|GRIS|X59AWG | E481: BYER
B482: 9 | C482: JOSE PABLO AGUILAR HERNANDEZ | D482: AVEO|2025|PERSUASION|MXM502C | E482: JGD
B483: 9 | C483: IVAN GENARO BOCANEGRA MARTINEZ | D483: AVEOH|2026|ROJO|NEZ101C | E483: ASHC
B484: 9 | C484: JOSE JUAN HERNANDEZ MEJIA | D484: AVEO|2025|PERSUASION|MXM502C | E484: ASHC
B485: 9 | C485: JORGE ALEJANDRO HERNANDEZ VALLEJO | D485: VERSA|2020|BLANCO|A35BHD | E485: ASHC
B486: 9 | C486: JUAN CARLOS CASTRO CASTILLO | D486: VERSA|2021|BLANCO|MEE228C | E486: ASHC
B487: 9 | C487: JORGE LUIS MEJIA LEOBARDO | D487: AVEO|2018|ROJO|R51BKD | E487: ASHC
... B541: 9 | C541: ABRAHAM RODRIGUEZ HERNANDEZ | D541: VENTO|2019|BLANCO|LUE965C | E541: U64
B542: 9 | C542: ULISES SANCHEZ HERNANDEZ | E542: U64
B543: 9 | C543: PEDRO ARELLANO PEREZ | D543: AVEO|2022|AZUL|MUF515A | E543: ASHC
B544: 9 | C544: LUIS AXEL RODRIGUEZ RANGEL | D544: AVEO|2019|BLANCO|NBS225A | E544: ASHC
B545: 9 | C545: FREDY PANTALEON VILLALOBOS | D545: AVEO|2019|BLANCO|NBS225A | E545: ASHC
B546: 9 | C546: CESAR AXEL SANTIAGO GARCIA | D546: VERSA|2020|BLANCO|A35BHD | E546: ASHC
B547: 9 | C547: EMMANUEL LARA HERNANDEZ | D547: BMW|2025|NEGRA|40K216 | E547: ASHC
B548: 9 | C548: ANTONIO GUZMAN BARRON | E548: JGD
B549: 10 | C549: VERONICA POBLANO LOPEZ | D549: MARCH|2019|TURQ|MAY737C | E549: JGD
B550: 10 | C550: ABRAHAM RODRIGUEZ HERNANDEZ | D550: VERSA|2022|GRIS|NES596C | E550: ASHC
B551: 10 | C551: ROBERTO HERNANDEZ GRANADOS | D551: MARCH|2019|TURQ|MAY737C | E551: ASHC
B552: 10 | C552: ALEJANDRO VELAZQUEZ VARGAS | D552: AVEO|2022|AZUL|NZY685B | E552: BYER
B553: 10 | C553: JOSE LUIS PEDRAZA AVILA | D553: AVEO|2019|PLATA|NEL860A | E553: ASHC
...

Sheet BASE DATOS
A1: AÑO | B1: SEM | C1: CONDUCTOR | D1: AUTO | E1: SOCIO | F1: PLATAFORMA | G1: APP | H1: GANANCIAS TOTALES | I1: META | J1: FIANZA | K1: COMENTARIO
A2: 2025 | B2: 1 | C2: ADOLFO LOPEZ MARTINEZ | D2: AVEO|2021|OCRE|NEB156A | E2: ASHC | F2: IVETH | G2: UBER | H2: 2143.1396 | I2: 2500
A3: 2025 | B3: 1 | C3: ARACELI CASTILLO GUERRERO | D3: AVEO|2018|GRIS|X59AWG | E3: ASHC | F3: ASHC | G3: UBER | H3: 2142.85 | I3: 2500
A4: 2025 | B4: 1 | C4: CESAR PIÑA BARONA | D4: HYUNDAI|2022|PLATA|D40BKD | E4: ASHC | F4: IVETH | G4: UBER | H4: 2210.15 | I4: 2500
A5: 2025 | B5: 1 | C5: CLAUDIA LEAÑOS | D5: KIA RIO|2017|ROJO|MYE912A | E5: U64 | F5: ASHC | G5: UBER | H5: 2653.1484 | I5: 2500
A6: 2025 | B6: 1 | C6: IVAN MOGUEL PULIDO | D6: VERSA|2023|PLATA|NCT814A | E6: ASHC | F6: ASHC | G6: UBER | H6: 1214.28 | I6: 2500
A7: 2025 | B7: 1 | C7: JESUS AURELIO NUNGARAY CASTILLO | D7: VENTO|2020|GRIS|R66BER | E7: ASHC | F7: ASHC | G7: UBER | H7: 2827.0928 | I7: 2500
A8: 2025 | B8: 1 | C8: JORGE VAZQUEZ HERNANDEZ | D8: AVEO|2018|GRIS|X59AWG | E8: ASHC | F8: ASHC | G8: UBER | H8: 2142.85 | I8: 2500
A9: 2025 | B9: 1 | C9: JOSE GUADALUPE GARCIA MORALES | D9: MARCH|2020|TURQ|N15BKD | E9: ASHC | F9: ASHC | G9: UBER | H9: 2643.796 | I9: 2500
A10: 2025 | B10: 1 | C10: JOSE JUAN HERNANDEZ MEJIA | D10: VERSA|2017|ACERO|X24APU | E10: ASHC | F10: ASHC | G10: UBER | H10: 3018.6268 | I10: 2500
A11: 2025 | B11: 1 | C11: OSCAR BLANCAS NORIEGA | D11: VENTO|2017|GRIS|NZV7888 | E11: ASHC | F11: ASHC | G11: UBER | H11: 3534.468 | I11: 2500
A12: 2025 | B12: 1 | C12: ULISES ITIEL CASTILLO AVILA | D12: KIA RIO|2020|GRIS|NCK475B | E12: ASHC | F12: IVETH | G12: UBER | H12: 2142.85 | I12: 2500
A13: 2025 | B13: 2 | C13: ABRAHAM ESCOBEDO ESCALANTE | D13: BEAT|2020|GRIS|NFN014B | E13: U64 | F13: ASHC | G13: UBER | H13: -210.852 | I13: 2500
... A30: 2025 | B30: 3 | C30: ADOLFO LOPEZ MARTINEZ | D30: AVEO|2021|OCRE|NEB156A | E30: ASHC | F30: ASHC | G30: UBER | H30: 1071.62 | I30: 2500
A31: 2025 | B31: 3 | C31: ADOLFO LOPEZ MARTINEZ | D31: AVEO|2021|OCRE|NEB156A | E31: ASHC | F31: IVETH | G31: UBER | H31: 1429.2988
A32: 2025 | B32: 3 | C32: ARACELI CASTILLO GUERRERO | D32: AVEO|2018|GRIS|X59AWG | E32: ASHC | F32: ASHC | G32: UBER | H32: 2499.19 | I32: 2500
A33: 2025 | B33: 3 | C33: CESAR PIÑA BARONA | D33: HYUNDAI|2022|PLATA|D40BKD | E33: ASHC | F33: ASHC | G33: UBER | H33: 2371 | I33: 2500
A34: 2025 | B34: 3 | C34: CESAR PIÑA BARONA | D34: HYUNDAI|2022|PLATA|D40BKD | E34: ASHC | F34: IVETH | G34: UBER | H34: 1429
A35: 2025 | B35: 3 | C35: CLAUDIA LEAÑOS | D35: KIA RIO|2017|ROJO|MYE912A | E35: U64 | F35: ASHC | G35: UBER | H35: 0 | I35: 2500
A36: 2025 | B36: 3 | C36: DIEGO SANCHEZ | D36: VENTO|2020|GRIS|R66BER | E36: ASHC | F36: ASHC | G36: UBER | H36: 3019.8424 | I36: 2500
A37: 2025 | B37: 3 | C37: EDGAR GEOVANY URIBE | D37: AVEO|2019|PLATA|NEL860A | E37: ASHC | F37: ASHC | G37: UBER | H37: 3000 | I37: 2500
A38: 2025 | B38: 3 | C38: FERNANDO ESQUIVEL SOSA | D38: VENTO|2018|AMARILLO|PED1652 | E38: ASHC | F38: ASHC | G38: UBER | H38: 2468 | I38: 2500
A39: 2025 | B39: 3 | C39: IRAM HERNANDEZ | D39: AVEO|2022|AZUL|MUF515A | E39: ASHC | F39: ASHC | G39: UBER | H39: 2800 | I39: 2500
A40: 2025 | B40: 3 | C40: IVAN MOGUEL PULIDO | D40: VERSA|2023|PLATA|NCT814A | E40: ASHC | F40: ASHC | G40: UBER | H40: 4500 | I40: 2500
A41: 2025 | B41: 3 | C41: JORGE VAZQUEZ HERNANDEZ | D41: AVEO|2018|GRIS|X59AWG | E41: ASHC | F41: ASHC | G41: UBER | H41: 357.15 | I41: 2500
A42: 2025 | B42: 3 | C42: JOSE GUADALUPE GARCIA MORALES | D42: MARCH|2020|TURQ|N15BKD | E42: ASHC | F42: ASHC | G42: UBER | H42: 3654.5425 | I42: 2500
A43: 2025 | B43: 3 | C43: JOSE GUILLERMO HERNANDEZ RAMIREZ | D43: AVEO|2018|ROJO|R51BKD | E43: U64 | F43: ASHC | G43: UBER | H43: 3000 | I43: 2500
A44: 2025 | B44: 3 | C44: JOSE JUAN HERNANDEZ MEJIA | D44: VERSA|2017|ACERO|X24APU | E44: ASHC | F44: ASHC | G44: UBER | H44: 3558.2585 | I44: 2500
A45: 2025 | B45: 3 | C45: JUAN CARLOS MUÑOZ | D45: AVEO|2019|BLANCO|NBS225A | E45: ASHC | F45: IVETH | G45: UBER | H45: 1320.4816 | I45: 2500
A46: 2025 | B46: 3 | C46: OSCAR BLANCAS NORIEGA | D46: VENTO|2017|GRIS|NZV7888 | E46: ASHC | F46: ASHC | G46: UBER | H46: 2799.8493 | I46: 2500
A47: 2025 | B47: 3 | C47: ULISES ITIEL CASTILLO AVILA | D47: KIA RIO|2020|GRIS|NCK475B | E47: ASHC | F47: ASHC | G47: UBER | H47: 1071 | I47: 2500
A48: 2025 | B48: 3 | C48: ULISES ITIEL CASTILLO AVILA | D48: KIA RIO|2020|GRIS|NCK475B | E48: ASHC | F48: IVETH | G48: UBER | H48: 1429
A49: 2025 | B49: 4 | C49: ADOLFO LOPEZ MARTINEZ | D49: AVEO|2021|OCRE|NEB156A | E49: ASHC | F49: IVETH | G49: UBER | H49: 2500 | I49: 2500
A50: 2025 | B50: 4 | C50: ARACELI CASTILLO GUERRERO | D50: AVEO|2018|GRIS|X59AWG | E50: ASHC | F50: ASHC | G50: UBER | H50: -400 | I50: 2500
A51: 2025 | B51: 4 | C51: CESAR PIÑA BARONA | D51: HYUNDAI|2022|PLATA|D40BKD | E51: ASHC | F51: IVETH | G51: UBER | H51: -2500 | I51: 2500
A52: 2025 | B52: 4 | C52: DIEGO SANCHEZ | D52: VENTO|2020|GRIS|R66BER | E52: ASHC | F52: ASHC | G52: UBER | H52: 3000.1 | I52: 2500
A53: 2025 | B53: 4 | C53: EDGAR GEOVANY URIBE | D53: AVEO|2019|PLATA|NEL860A | E53: ASHC | F53: ASHC | G53: UBER | H53: 3000 | I53: 2500
A54: 2025 | B54: 4 | C54: FERNANDO ESQUIVEL SOSA | D54: VENTO|2018|AMARILLO|PED1652 | E54: ASHC | F54: ASHC | G54: UBER | H54: 3000 | I54: 2500
A55: 2025 | B55: 4 | C55: IRAM HERNANDEZ | D55: AVEO|2022|AZUL|MUF515A | E55: ASHC | F55: ASHC | G55: UBER | H55: 3000 | I55: 2500
A56: 2025 | B56: 4 | C56: IVAN MOGUEL PULIDO | D56: VERSA|2023|PLATA|NCT814A | E56: ASHC | F56: ASHC | G56: UBER | H56: 3000 | I56: 2500
...

Sheet TABLAS BARRAS 
B1: CONDUCTOR | C1: (Varios elementos)
B3: AÑO | C3: SEM | D3: Suma de GANANCIAS TOTALES | E3: Suma de FIANZA | F3: Cuenta de META
B4: 2025 | C4: 2 | D4: -210.852 | F4: 1
C5: 3 | D5: -1733.5504 | F5: 1
B6: Total 2025 | D6: -1944.4024 | F6: 2
B7: 2026 | C7: 3 | D7: 857.14286 | E7: 1000 | F7: 1
C8: 4 | D8: 2999.52 | F8: 1
C9: 5 | D9: 2963.8571 | F9: 1
C10: 6 | D10: 3199.78 | F10: 1
C11: 7 | D11: 3200.46 | F11: 1
C12: 8 | D12: 3199.76 | F12: 1
C13: 9 | D13: 2864.1429 | F13: 1
C14: 10 | D14: 3424.4 | F14: 1
C15: 11 | D15: 3014.1439 | F15: 1
C16: 12 | D16: 3399.66 | F16: 1
B17: Total 2026 | D17: 29122.867 | E17: 1000 | F17: 10
B18: Total general | D18: 27178.464 | E18: 1000 | F18: 12

Sheet CTRL AUTOS
A1: SEM | B1: CONDUCTOR | C1: AUTO
A2: 7 | B2: LUIS EDGARDO AYALA ALVAREZ | C2: VENTO|2020|GRIS|R66BER
A3: 7 | B3: SIN ASIGNAR | C3: AVEO|2022|AZUL|MUF515A
A4: 7 | B4: SIN ASIGNAR | C4: AVEO|2018|ROJO|R51BKD
A5: 7 | B5: VICTOR HUGO RUIZ CASTILLO | C5: AVEO|2019|PLATA|NEL860A
A6: 7 | B6: LUIS AXEL RODRIGUEZ RANGEL | C6: AVEO|2019|BLANCO|NBS225A
A7: 7 | B7: OSCAR IVAN MIÑON RAMIREZ | C7: MARCH|2020|TURQ|N15BKD
A8: 7 | B8: EDUARDO RIVERA LAVIN | C8: KIA RIO|2017|ROJO|MYE912A
A9: 7 | B9: SIN ASIGNAR | C9: AVEO|2018|GRIS|X59AWG
A10: 7 | B10: DAVID ROMERO JAIME | C10: BEAT|2020|GRIS|NFN014B
A11: 7 | B11: RODOLFO VILLEDA MACIAS | C11: VENTO|2017|GRIS|MMA672C
A12: 7 | B12: SAUL DOMINGUEZ VAZQUEZ | C12: VERSA|2023|PLATA|NCT814A
A13: 7 | B13: ARMANDO MARTINEZ VELAZQUEZ | C13: HYUNDAI|2022|PLATA|D40BKD
... A232: 3 | B232: OSCAR IVAN MIÑON RAMIREZ | C232: MARCH|2020|TURQ|N15BKD
A233: 3 | C233: KIA RIO|2017|ROJO|MYE912A
A234: 3 | B234: JONATHAN BERNAL RODRIGUEZ | C234: AVEO|2018|GRIS|X59AWG
A235: 3 | B235: DAVID ROMERO JAIME | C235: BEAT|2020|GRIS|NFN014B
A236: 3 | B236: YOSHUA JARETH VALDEZ HERNANDEZ | C236: VENTO|2017|GRIS|MMA672C
A237: 3 | B237: FRANCISCO GOMEZ URQUIZA SILVA | C237: VERSA|2023|PLATA|NCT814A
A238: 3 | B238: ARMANDO MARTINEZ VELAZQUEZ | C238: HYUNDAI|2022|PLATA|D40BKD
A239: 3 | B239: CAMILO IESUA MEJIA DIAZ | C239: KIA RIO|2020|GRIS|NCK475B
A240: 3 | B240: SERGIO BALDERAS BAEZ | C240: AVEO|2022|AZUL|NZY685B
A241: 3 | B241: SIN ASIGNAR | C241: VENTO|2018|AMARILLO|PED1652
A242: 3 | B242: EDUARDO LICONA GODINEZ | C242: KIA RIO|2020|ROJO|MFP751C
A243: 3 | B243: ADOLFO LOPEZ MARTINEZ | C243: VERSA|2020|ROJO|NLP172B
A244: 3 | B244: FRANCISCO ISLAS CHAVEZ | C244: AVEO|2024|GRIS|LRL009C
A245: 3 | B245: ALFONSO GONZALEZ | C245: SWIFT|2017|ROJO|X89ALV
... A274: 3 | B274: GERMAN LUSARRETA ROMERO | C274: AVEO|2026|ROJO|NEZ108C
A275: 3 | C275: AVEO H|2026|BLANCO
A276: 3 | C276: AVEO H|2026|BLANCO
A277: 3 | C277: AVEO H|2026|BLANCO
A278: 3 | C278: AVEO H|2026|BLANCO
A279: 3 | C279: AVEO H|2026|BLANCO
A280: 3 | C280: AVEO H|2026|BLANCO
A281: 2 | B281: KEVIN ALEXIS MERLOS CORTES | C281: VENTO|2020|GRIS|R66BER
A282: 2 | B282: XAVIER ALAN LARA JIMENEZ | C282: AVEO|2022|AZUL|MUF515A
A283: 2 | B283: FERNANDO GARRIDO GARNICA | C283: AVEO|2018|ROJO|R51BKD
A284: 2 | B284: JUAN CARLOS ZEA CRUZ | C284: AVEO|2019|PLATA|NEL860A
A285: 2 | B285: JOEL RAUL PEREA PEÑA | C285: AVEO|2019|BLANCO|NBS225A
A286: 2 | B286: OSCAR IVAN MIÑON RAMIREZ | C286: MARCH|2020|TURQ|N15BKD
...

Sheet Hoja1
